Workbook

Sheet Sumário
A1: NORMATEL • Diagnóstico de Efetivo
A2: Fonte única: aba EFETIVO 11.05.2026 • Fórmulas vivas referenciando a base
B4: Visão Geral
B5: Esta planilha consolida o quadro de pessoal dos projetos 741 e 743 a partir da aba EFETIVO 11.05.2026. Todas as análises usam fórmulas dinâmicas (COUNTIFS, SUMPRODUCT) referenciando a base - basta atualizar a aba de efetivo (SIT, PROJETO, BASE, FUNÇÃO) e os números recalculam automaticamente. Filtros aplicados: somente registros com SIT = 'A' (ativo) ou SIT = 'D' (desligado). Identificação de projeto pela presença de '741' ou '743' na coluna PROJETO.
B7: ATIVOS 741 | G7: DESLIGADOS 741
B8: {=SUMPRODUCT(ISNUMBER(SEARCH("741",'EFETIVO 11.05.2026'!$H$2:$H$1919))*('EFETIVO 11.05.2026'!$G$2:$G$1919="A"))} -> 185 | G8: {=SUMPRODUCT(ISNUMBER(SEARCH("741",'EFETIVO 11.05.2026'!$H$2:$H$1919))*('EFETIVO 11.05.2026'!$G$2:$G$1919="D"))} -> 87
B10: ATIVOS 743 | G10: DESLIGADOS 743
B11: {=SUMPRODUCT(ISNUMBER(SEARCH("743",'EFETIVO 11.05.2026'!$H$2:$H$1919))*('EFETIVO 11.05.2026'!$G$2:$G$1919="A"))} -> 319 | G11: {=SUMPRODUCT(ISNUMBER(SEARCH("743",'EFETIVO 11.05.2026'!$H$2:$H$1919))*('EFETIVO 11.05.2026'!$G$2:$G$1919="D"))} -> 101
B13: ATIVOS 736 | G13: DESLIGADOS 736
B14: {=SUMPRODUCT(ISNUMBER(SEARCH("736",'EFETIVO 11.05.2026'!$H$2:$H$1919))*('EFETIVO 11.05.2026'!$G$2:$G$1919="A"))} -> 399 | G14: {=SUMPRODUCT(ISNUMBER(SEARCH("736",'EFETIVO 11.05.2026'!$H$2:$H$1919))*('EFETIVO 11.05.2026'!$G$2:$G$1919="D"))} -> 180
B16: ATIVOS 737 | G16: DESLIGADOS 737
B17: {=SUMPRODUCT(ISNUMBER(SEARCH("737",'EFETIVO 11.05.2026'!$H$2:$H$1919))*('EFETIVO 11.05.2026'!$G$2:$G$1919="A"))} -> 406 | G17: {=SUMPRODUCT(ISNUMBER(SEARCH("737",'EFETIVO 11.05.2026'!$H$2:$H$1919))*('EFETIVO 11.05.2026'!$G$2:$G$1919="D"))} -> 145
B19: TOTAL ATIVOS | G19: AFASTADOS (F/P/T/M)
B20: {=SUMPRODUCT(('EFETIVO 11.05.2026'!$G$2:$G$1919="A")*1)} -> 1309 | G20: {=SUMPRODUCT(('EFETIVO 11.05.2026'!$G$2:$G$1919="F")+('EFETIVO 11.05.2026'!$G$2:$G$1919="P")+('EFETIVO 11.05.2026'!$G$2:$G$1919="T")+('EFETIVO 11.05.2026'!$G$2:$G$1919="M"))} -> 89
B22: TOTAL REGS
B23: {=SUMPRODUCT((('EFETIVO 11.05.2026'!$G$2:$G$1919="A")+('EFETIVO 11.05.2026'!$G$2:$G$1919="D"))*1)} -> 1822
B26: Índice das Abas
B27: 1 | C27: Sumário | F27: Esta aba - KPIs gerais e índice
B28: 2 | C28: Análises 736 | F28: Mesma estrutura aplicada ao projeto 736 (614 registros)
B29: 3 | C29: Análises 737 | F29: Mesma estrutura aplicada ao projeto 737 (586 registros)
B30: 4 | C30: Análises 741 | F30: 5 seções com fórmulas vivas: KPIs, headcount por função, base, pontos únicos, movimentação histórica
B31: 5 | C31: Análises 743 | F31: Mesma estrutura aplicada ao projeto 743
B32: 6 | C32: EFETIVO 11.05.2026 | F32: FONTE ÚNICA. Atualize SIT, PROJETO, BASE, FUNÇÃO aqui e tudo recalcula automaticamente.
B33: 7 | C33: EFETIVO 20.10.2025 | F33: Base histórica para referência (não conectada às fórmulas)
B34: 8 | C34: 741 EFTV ATUALIZADO | F34: Base auxiliar do 741 (com classificação por Grupo/Área)
B35: 9 | C35: FG-ORGANOGRAMA-741 | F35: Organograma desenhado do projeto 741
B36: 10 | C36: FG-ORGANOGRAMA-743 | F36: Organograma desenhado do projeto 743
B37: 11 | C37: ORG. RESUMIDO-741 | F37: Versão executiva do organograma 741
B38: 12 | C38: ORG-RESUMIDO-743 | F38: Versão executiva do 743 (atualmente vazia, será preenchida)
B40: Notas Metodológicas
B41: -1 | C41: Todos os números desta planilha vêm de fórmulas que referenciam a aba EFETIVO 11.05.2026. Edições em SIT, PROJETO, BASE ou FUNÇÃO refletem nas análises imediatamente.
B42: -2 | C42: Identificação de projeto: SUMPRODUCT + ISNUMBER(SEARCH("741"...)) ou SEARCH("743"...) na coluna PROJETO. Funciona mesmo que o texto venha completo (ex.: 'PROJETO 741 - FACILITIES MULT CABIUNAS UTE/AE-SINTRAINDISTAL').
B43: -3 | C43: Filtro padrão: SIT = 'A' (ativo) ou SIT = 'D' (desligado). Outros valores (F/V/P/T/M) são ignorados nas seções de Headcount/Funções.
B44: -4 | C44: Movimentação histórica: o ano é extraído com YEAR() das colunas ADMISSÃO (entradas) e DEMISSÃO (saídas). Em 'D' já desligados, a contagem de ATIVO/DESLIGADO conta o registro pelo seu status final.
B45: -5 | C45: Pontos Únicos de Falha (Seção 4): funções com exatamente 1 ocupante ativo. Resultado dinâmico via INDEX/SMALL - quando uma função ganhar ou perder ocupante, a lista se ajusta sozinha.
B47: 🔒 Acesso Restrito
B48: As abas abaixo estão protegidas. Clique no botão correspondente e informe a senha para visualizar. Ao retornar ao Sumário, a aba é ocultada novamente automaticamente.
B50: Aba | C50: Descrição | F50: Acesso
B51: FG-ORGANOGRAMA-736 | C51: Organograma completo do projeto 736
B52: FG-ORGANOGRAMA-737 | C52: Organograma completo do projeto 737
...

Sheet FG-ORGANOGRAMA-741
CU4: Gerente Regional
CT5: DIEGO CASTELUBER BASSETTI
CT10: 0.5 | CU10: Gerente de Facilities | DU10: Engenheiro de Segurança | FF10: Gerente Administrativo
CT11: JOSE DANIEL SILVA SANTOS JUNIOR | DT11: RODRIGO RODRIGUES | FE11: EVANDO GERONIMO
AS12: =SUM(AJ13+AJ15) -> 1 | CM12: =SUM(CD13+CD16+CD18+CD20+CD22) -> 5
AJ13: 0.5 | AK13: Assistente Administrativo | BG13: 0.5 | BH13: Supervisor Administrativo | CD13: 1 | CE13: Supervisor de Planejamento
AJ14: GABRIEL SERAFIM DA CRUZ | BG14: MAICON MONTEIRO | CD14: PEDRO PAULO TAVARES BARBOSA MACHADO | EP14: =SUM(DT20+DK24+DK26+DT24+DT26+DT28+DT30+DT32+EC24+EC26+EC28+DT17) -> 9.5 | FE14: =SUM(EV18+EV20) -> 2 | FW14: =SUM(FN20+FN22+FN24) -> 3
AJ15: 0.5 | AK15: Assistente Administrativo | EH15: Tecnico de Enfermagem | EW15: Supervisora Administrativo | FO15: Supervisor Administrativo
AJ16: RAPHAEL DURAO SENOS DE CAMPOS | CD16: 1 | CE16: Planejador | EG16: CLEITON ORILIO LIRA DA SILVA
BI17: =SUM(AZ18+AZ22+AZ24+AZ26+AZ28+AZ30) -> 5 | BW17: =SUM(BN18+BN20+BN22+BN24+BN26) -> 4.5 | CD17: TAIANE TEIXEIRA DA SILVA DE OLIVEIRA | DT17: 0.5 | DU17: Supervisora de SMS
AP18: Software | AZ18: 1 | BA18: Assistente de Logistica I | BN18: 1 | BO18: Comprador - Normatel | CD18: 1 | CE18: Planejador | DT18: DANIELE LIMA PONTES | EV18: 1 | EW18: Auxiliar Administrativo | FN18: 1 | FO18: Almoxarife
AZ19: IZABELLA DE JESUS LIMA | BN19: DIEGO GREGORIO HESPANHOL | CD19: ALESSANDRA DA SILVA MARIANO | EV19: MICHELE VIEIRA SOUZA | FN19: ADENILSON LUIZ DA SILVA
AZ20: 1 | BA20: Assistente de Logistica I | BN20: 1 | BO20: Comprador - Normatel | CD20: 1 | CE20: Assistente Administrativo | DT20: 0.5 | DU20: Tecnico de Segurança II | EV20: 1 | EW20: Auxiliar Administrativo | FN20: 1 | FO20: Almoxarife
AZ21: THAINANDA DOS SANTOS SOUZA LEONE | BN21: VITOR DANIEL RODRIGUES DE CARVALHO MATOS | CD21: KARINY CORREA REIS | DT21: HERALDO JULIO GREGORIO DA SILVA | EV21: JULIA FRANCO SOUZA | FN21: VANESSA DE OLIVEIRA MACHARETE
AZ22: 1 | BA22: Motorista | BN22: 1 | BO22: Comprador - Petrobras | CD22: 1 | CE22: Assistente Administrativo | FN22: 1 | FO22: Auxiliar de Almoxarifado
AZ23: GERALDO ALVES BEZERRA | BN23: IONE DE FREIRAS | CD23: EDUARDA MANHAES VELASCO | DK23: DOCUMENTAÇÃO | DT23: ÁREA / DOCUMENTAÇÃO | EC23: INSPEÇÃO | FB23: RH | FN23: WEBERSON DA PAIXAO DE ARAUJO SILVA
AZ24: 1 | BA24: Motorista | BN24: 1 | BO24: Comprador - Petrobras | DK24: 1 | DL24: Auxiliar de SMS | DT24: 1 | DU24: Tecnico de Segurança | EC24: 0.5 | ED24: Tecnico de Segurança | FN24: 1 | FO24: Auxiliar de Almoxarifado
AZ25: JOABSON DE OLIVEIRA FERREIRA | BN25: NIVIA RANGEL | CJ25: Planejamento | DK25: IZADORA MONTEIRO CARVALHO | DT25: FILIPE DE PAULA DA SILVA | EC25: RAFAELA GAUDENCIO MAXIMO | FN25: DALISSON CARDOSO FERREIRA
AZ26: 1 | BA26: Motorista | BN26: 0.5 | BO26: Comprador - Petrobras | DK26: 1 | DL26: Auxiliar de SMS | DT26: 1 | DU26: Tecnico de Segurança | EC26: 0.5 | ED26: Tecnico de Segurança
AZ27: CLAUDIO MONTEIRO ANDRE | BN27: CRISTIANO PAIVA | DK27: LAURAH HECTH FELIX | DT27: MARIA FERNANDA SILVA SANTOS | EC27: SANDRO AUGUSTO SOUZA DO COUTO | FT27: Suprimentos
AZ28: 0.5 | BA28: Operador de Retroesvacadeira | DT28: 1 | DU28: Tecnico de Segurança | EC28: 0.5 | ED28: Tecnico de Segurança
AZ29: VAGA | BT29: Compras | DT29: VAGA | EC29: MATEUS HIPOLITO CHAGAS RIBEIRO
AZ30: 0.5 | BA30: Motorista Munckeiro | DT30: 1 | DU30: Tecnico de Segurança
AZ31: UENDER DA SILVA GOMES | DT31: LEONARDO LOUSA DA SILVA
DT32: 1 | DU32: Tecnico de Segurança
BF33: Logística | DT33: MARIA LUIZA DE FATIMA ALFARO
EM35: SMS
CT40: 1 | CU40: Preposto
CT41: ALEXANDRO DOS REIS JUNIOR
CT43: 1 | CU43: Coordenador de Manutenção
CT44: ANA CAROLINA RODRIGUES
CT48: AREAS EXTERNAS
AJ55: =SUM(T56+M62+M64+M66+M68+AA62+AA64+AA66+AA68+AA70+AA72+AA74) -> 12 | CO55: =SUM(BO59+AX64+AX66+BH64+BH66+BV64+BV66+CF64+AX76+AX78+AX80+AX82+AX84+AX86+AX88+AX90+BH76+BH78+BV76+CF76+CF78+CF80+CF82+CF84+CF86+CF88+BO56+BH68+BV80+BV78+BH80+BH82) -> 25.5
T56: 1 | U56: Supervisor de Eletrica | BO56: 0.5 | BP56: Engenheira Civil | DT56: 0.5 | DU56: Engenheiro Agronomo
T57: RODRIGO COTA SANTOS | BO57: KARLA KOPPE BATISTA | DT57: GUSTAVO FABRI BASTOS
BO59: 1 | BP59: Supervisor de Manutencao Civil | DX59: =SUM(DJ60+DJ63+DE66+DE68+DE70+DE72+DO142+DE76+DE78+DE80+DE82+DO66+DO68+DO70+DO72+DO74+DO76+DO78+DO80+DO82) -> 20 | EK59: =SUM(EB60+EB63+EB66+EB68+EB70+EB72+EB74+EB76+EB78+EB80+EB82+EB84+EB86+EB88+EB90+EB92) -> 15.5
BO60: ARVIDO BALANIUK JUNIOR | DJ60: 1 | DK60: Supervisor de Áreas Verdes | EB60: 0.5 | EC60: Supervisor de Limpeza
M61: MECANICA | AA61: ELETRICA | DJ61: JEFFERSON DE SOUZA CUNHA | EB61: TIAGO DIOGO SANTOS DA COSTA
M62: 1 | N62: Tecnico de Mecanica | AA62: 1 | AB62: Tecnico em Eletrotecnica
M63: GEFERSON RODRIGUES SIMPLICIO | AA63: FERNANDO SILVA ALVARENGA | AX63: ANDAIMES | BH63: APOIO TÉCNICO | BV63: HIDRAULICA | CF63: DRONE | DJ63: 1 | DK63: Encarregado de Áreas Verdes | EB63: 1 | EC63: Encarregado de Limpeza
...

Sheet ORG. RESUMIDO-741
X3: Gerente Regional
W4: DIEGO CASTELUBER BASSETTI
W7: 0.5 | X7: Gerente de Facilites | AX7: Gerente de SMS | BK7: Gerente ADM
W8: JOSE DANIEL SILVA SANTOS JUNIOR | AW8: RODRIGO CESAR RODRIGUES | BJ8: EVANDO GERONIMO
P10: EQUIPE ESTRATÉGICA
P11: GERÊNCIA DE INTEGRAÇÃO | AX11: QUALIDADE, SAÚDE SEGURANÇA E MEIO AMBIENTE | BB11: EQUIPE DE SAUDE | BK11: RH | BO11: ALMOXARIFADO
W15: ='FG-ORGANOGRAMA-741'!BG13 -> 0.5 | X15: Supervisor Administrativo | AG15: ='FG-ORGANOGRAMA-741'!CD13 -> 1 | AH15: Supervisora de Planejamento
W16: MAICON MONTEIRO | AG16: PEDRO PAULO TAVARES BARBOSA MACHADO
P18: SOFTWARE | X18: LOGÍSTICA | AA18: COMPRAS | AJ18: PLANEJAMENTO
AX21: ='FG-ORGANOGRAMA-741'!EP14 -> 9.5 | BB21: 0 | BK21: ='FG-ORGANOGRAMA-741'!EV18 -> 1 | BO21: ='FG-ORGANOGRAMA-741'!FW14 -> 3
P28: ='FG-ORGANOGRAMA-741'!AS12 -> 1 | X28: ='FG-ORGANOGRAMA-741'!AZ22+'FG-ORGANOGRAMA-741'!AZ24+'FG-ORGANOGRAMA-741'!AZ26+'FG-ORGANOGRAMA-741'!AZ28+'FG-ORGANOGRAMA-741'!AZ30 -> 4 | AA28: =SUM('FG-ORGANOGRAMA-741'!BI17,'FG-ORGANOGRAMA-741'!BW17) -> 9.5 | AJ28: ='FG-ORGANOGRAMA-741'!CM12 -> 5
AO33: 1 | AP33: Preposto
AO34: ALEXANDRO DOS REIS JUNIOR
AO36: 1 | AP36: Coordenador de Manutenção
AO37: ANA CAROLINA RODRIGUES
T40: Áreas Externas | AQ40: Tapera | BN40: UTE-TMA
H44: 0.5 | I44: Supervisor de Manutenção II | R44: 0.5 | S44: Engenheiro Civil | AB44: 0.5 | AC44: Engenheiro Agronomo | AP44: Supervisor de Manutenção II | BB44: 0.5 | BC44: Supervisor de Manutenção II | BL44: 0.5 | BM44: Engenheiro Civil | BV44: 0.5 | BW44: Engenheiro Agronomo
H45: LAFAETE DAUMAS BRAGA DE MORAES | R45: KARLA KOPPE BATISTA | AB45: GUSTAVO FABRI BASTOS | AO45: LAFAETE DAUMAS BRAGA DE MORAES | BB45: LAFAETE DAUMAS BRAGA DE MORAES | BL45: KARLA KOPPE BATISTA | BV45: GUSTAVO FABRI BASTOS
K47: MANUTENÇÃO | U47: CIVIL | AD47: ÁREAS VERDES | AG47: CONS. LIMPEZA | AP47: ÁREAS VERDES | AS47: CONS. LIMPEZA | BE47: MANUTENÇÃO | BO47: CIVIL | BX47: ÁREAS VERDES | CA47: CONS. LIMPEZA
K57: ='FG-ORGANOGRAMA-741'!AJ55 -> 12 | U57: ='FG-ORGANOGRAMA-741'!CO55 -> 25.5 | AD57: ='FG-ORGANOGRAMA-741'!DX59 -> 20 | AG57: ='FG-ORGANOGRAMA-741'!EK59 -> 15.5 | AP57: ='FG-ORGANOGRAMA-741'!CV184 -> 2 | AS57: ='FG-ORGANOGRAMA-741'!DH184 -> 1 | BE57: ='FG-ORGANOGRAMA-741'!AJ105 -> 15 | BO57: ='FG-ORGANOGRAMA-741'!CP105 -> 35.5 | BX57: ='FG-ORGANOGRAMA-741'!DX109 -> #REF! | CA57: ='FG-ORGANOGRAMA-741'!EK109 -> 15.5
AM64: TOTAL | AQ64: =SUM(W3+W7+M15+W15+AG15+P28+X28+AA28+AJ28+AW7+AX21+BB21+BJ7+BK21+BO21+AO33+AO36+H44+R44+AB44+K57+U57+AD57+AG57+AO44+AP57+AS57+BB44+BE57+BL44+BO57+BV44+BX57+CA57) -> #REF!

Sheet Análises 741
A1: NORMATEL • Análises Projeto 741
A2: Cálculos dinâmicos sobre EFETIVO 11.05.2026 - Situações (SIT): A=Ativo, D=Desligado, F=Férias, P=INSS, T=Acidente de Trabalho, M=Serviço Militar
B4: 1. Indicadores do Projeto 741
B5: Total de registros vinculados ao 741 (todas situações) | C5: {=SUMPRODUCT(ISNUMBER(SEARCH("741",'EFETIVO 11.05.2026'!$H$2:$H$712))*(('EFETIVO 11.05.2026'!$G$2:$G$712="A")+('EFETIVO 11.05.2026'!$G$2:$G$712="D")+('EFETIVO 11.05.2026'!$G$2:$G$712="F")+('EFETIVO 11.05.2026'!$G$2:$G$712="P")+('EFETIVO 11.05.2026'!$G$2:$G$712="T")+('EFETIVO 11.05.2026'!$G$2:$G$712="M")))} -> 278
B6: Ativos no 741 | C6: {=SUMPRODUCT(ISNUMBER(SEARCH("741",'EFETIVO 11.05.2026'!$H$2:$H$712))*('EFETIVO 11.05.2026'!$G$2:$G$712="A"))} -> 185
B7: Desligados no 741 | C7: {=SUMPRODUCT(ISNUMBER(SEARCH("741",'EFETIVO 11.05.2026'!$H$2:$H$712))*('EFETIVO 11.05.2026'!$G$2:$G$712="D"))} -> 87
B8: % de turnover (desligados / total) | C8: =IFERROR(C7/C5,0) -> 0.31294964
B9: Afastados no 741 (F+P+T+M) | C9: {=SUMPRODUCT(ISNUMBER(SEARCH("741",'EFETIVO 11.05.2026'!$H$2:$H$712))*(('EFETIVO 11.05.2026'!$G$2:$G$712="F")+('EFETIVO 11.05.2026'!$G$2:$G$712="P")+('EFETIVO 11.05.2026'!$G$2:$G$712="T")+('EFETIVO 11.05.2026'!$G$2:$G$712="M")))} -> 6
B10: Funções distintas (ativos) | C10: {=SUMPRODUCT(--(C14:C71>0))} -> 50
B11: 2. Colaboradores por Função (Ativos / Desligados / Afastados)
B13: Função | C13: Ativos | D13: Desligados | E13: % do total ativos | F13: Afastados
B14: AJUDANTE DE CALDEIRARIA | C14: {=SUMPRODUCT(ISNUMBER(SEARCH("741",'EFETIVO 11.05.2026'!$H$2:$H$712))*('EFETIVO 11.05.2026'!$G$2:$G$712="A")*('EFETIVO 11.05.2026'!$C$2:$C$712="AJUDANTE DE CALDEIRARIA"))} -> 0 | D14: {=SUMPRODUCT(ISNUMBER(SEARCH("741",'EFETIVO 11.05.2026'!$H$2:$H$712))*('EFETIVO 11.05.2026'!$G$2:$G$712="D")*('EFETIVO 11.05.2026'!$C$2:$C$712="AJUDANTE DE CALDEIRARIA"))} -> 1 | E14: =IFERROR(C14/$C$6,0) -> 0 | F14: {=SUMPRODUCT(ISNUMBER(SEARCH("741",'EFETIVO 11.05.2026'!$H$2:$H$712))*(('EFETIVO 11.05.2026'!$G$2:$G$712="F")+('EFETIVO 11.05.2026'!$G$2:$G$712="P")+('EFETIVO 11.05.2026'!$G$2:$G$712="T")+('EFETIVO 11.05.2026'!$G$2:$G$712="M"))*('EFETIVO 11.05.2026'!$C$2:$C$712=$B14))} -> 0
B15: AJUDANTE DE ELETRICA PREDIAL | C15: {=SUMPRODUCT(ISNUMBER(SEARCH("741",'EFETIVO 11.05.2026'!$H$2:$H$712))*('EFETIVO 11.05.2026'!$G$2:$G$712="A")*('EFETIVO 11.05.2026'!$C$2:$C$712="AJUDANTE DE ELETRICA PREDIAL"))} -> 4 | D15: {=SUMPRODUCT(ISNUMBER(SEARCH("741",'EFETIVO 11.05.2026'!$H$2:$H$712))*('EFETIVO 11.05.2026'!$G$2:$G$712="D")*('EFETIVO 11.05.2026'!$C$2:$C$712="AJUDANTE DE ELETRICA PREDIAL"))} -> 0 | E15: =IFERROR(C15/$C$6,0) -> 0.021621622 | F15: {=SUMPRODUCT(ISNUMBER(SEARCH("741",'EFETIVO 11.05.2026'!$H$2:$H$712))*(('EFETIVO 11.05.2026'!$G$2:$G$712="F")+('EFETIVO 11.05.2026'!$G$2:$G$712="P")+('EFETIVO 11.05.2026'!$G$2:$G$712="T")+('EFETIVO 11.05.2026'!$G$2:$G$712="M"))*('EFETIVO 11.05.2026'!$C$2:$C$712=$B15))} -> 0
B16: AJUDANTE DE ELETROMECANICA PREDIAL | C16: {=SUMPRODUCT(ISNUMBER(SEARCH("741",'EFETIVO 11.05.2026'!$H$2:$H$712))*('EFETIVO 11.05.2026'!$G$2:$G$712="A")*('EFETIVO 11.05.2026'!$C$2:$C$712="AJUDANTE DE ELETROMECANICA PREDIAL"))} -> 3 | D16: {=SUMPRODUCT(ISNUMBER(SEARCH("741",'EFETIVO 11.05.2026'!$H$2:$H$712))*('EFETIVO 11.05.2026'!$G$2:$G$712="D")*('EFETIVO 11.05.2026'!$C$2:$C$712="AJUDANTE DE ELETROMECANICA PREDIAL"))} -> 2 | E16: =IFERROR(C16/$C$6,0) -> 0.016216216 | F16: {=SUMPRODUCT(ISNUMBER(SEARCH("741",'EFETIVO 11.05.2026'!$H$2:$H$712))*(('EFETIVO 11.05.2026'!$G$2:$G$712="F")+('EFETIVO 11.05.2026'!$G$2:$G$712="P")+('EFETIVO 11.05.2026'!$G$2:$G$712="T")+('EFETIVO 11.05.2026'!$G$2:$G$712="M"))*('EFETIVO 11.05.2026'!$C$2:$C$712=$B16))} -> 0
B17: AJUDANTE DE MANUTENCAO ELETRICA | C17: {=SUMPRODUCT(ISNUMBER(SEARCH("741",'EFETIVO 11.05.2026'!$H$2:$H$712))*('EFETIVO 11.05.2026'!$G$2:$G$712="A")*('EFETIVO 11.05.2026'!$C$2:$C$712="AJUDANTE DE MANUTENCAO ELETRICA"))} -> 1 | D17: {=SUMPRODUCT(ISNUMBER(SEARCH("741",'EFETIVO 11.05.2026'!$H$2:$H$712))*('EFETIVO 11.05.2026'!$G$2:$G$712="D")*('EFETIVO 11.05.2026'!$C$2:$C$712="AJUDANTE DE MANUTENCAO ELETRICA"))} -> 0 | E17: =IFERROR(C17/$C$6,0) -> 0.0054054054 | F17: {=SUMPRODUCT(ISNUMBER(SEARCH("741",'EFETIVO 11.05.2026'!$H$2:$H$712))*(('EFETIVO 11.05.2026'!$G$2:$G$712="F")+('EFETIVO 11.05.2026'!$G$2:$G$712="P")+('EFETIVO 11.05.2026'!$G$2:$G$712="T")+('EFETIVO 11.05.2026'!$G$2:$G$712="M"))*('EFETIVO 11.05.2026'!$C$2:$C$712=$B17))} -> 0
B18: AJUDANTE DE MECANICA PREDIAL | C18: {=SUMPRODUCT(ISNUMBER(SEARCH("741",'EFETIVO 11.05.2026'!$H$2:$H$712))*('EFETIVO 11.05.2026'!$G$2:$G$712="A")*('EFETIVO 11.05.2026'!$C$2:$C$712="AJUDANTE DE MECANICA PREDIAL"))} -> 2 | D18: {=SUMPRODUCT(ISNUMBER(SEARCH("741",'EFETIVO 11.05.2026'!$H$2:$H$712))*('EFETIVO 11.05.2026'!$G$2:$G$712="D")*('EFETIVO 11.05.2026'!$C$2:$C$712="AJUDANTE DE MECANICA PREDIAL"))} -> 0 | E18: =IFERROR(C18/$C$6,0) -> 0.010810811 | F18: {=SUMPRODUCT(ISNUMBER(SEARCH("741",'EFETIVO 11.05.2026'!$H$2:$H$712))*(('EFETIVO 11.05.2026'!$G$2:$G$712="F")+('EFETIVO 11.05.2026'!$G$2:$G$712="P")+('EFETIVO 11.05.2026'!$G$2:$G$712="T")+('EFETIVO 11.05.2026'!$G$2:$G$712="M"))*('EFETIVO 11.05.2026'!$C$2:$C$712=$B18))} -> 0
B19: AJUDANTE DE PEDREIRO | C19: {=SUMPRODUCT(ISNUMBER(SEARCH("741",'EFETIVO 11.05.2026'!$H$2:$H$712))*('EFETIVO 11.05.2026'!$G$2:$G$712="A")*('EFETIVO 11.05.2026'!$C$2:$C$712="AJUDANTE DE PEDREIRO"))} -> 0 | D19: {=SUMPRODUCT(ISNUMBER(SEARCH("741",'EFETIVO 11.05.2026'!$H$2:$H$712))*('EFETIVO 11.05.2026'!$G$2:$G$712="D")*('EFETIVO 11.05.2026'!$C$2:$C$712="AJUDANTE DE PEDREIRO"))} -> 2 | E19: =IFERROR(C19/$C$6,0) -> 0 | F19: {=SUMPRODUCT(ISNUMBER(SEARCH("741",'EFETIVO 11.05.2026'!$H$2:$H$712))*(('EFETIVO 11.05.2026'!$G$2:$G$712="F")+('EFETIVO 11.05.2026'!$G$2:$G$712="P")+('EFETIVO 11.05.2026'!$G$2:$G$712="T")+('EFETIVO 11.05.2026'!$G$2:$G$712="M"))*('EFETIVO 11.05.2026'!$C$2:$C$712=$B19))} -> 0
B20: AJUDANTE DE PINTURA | C20: {=SUMPRODUCT(ISNUMBER(SEARCH("741",'EFETIVO 11.05.2026'!$H$2:$H$712))*('EFETIVO 11.05.2026'!$G$2:$G$712="A")*('EFETIVO 11.05.2026'!$C$2:$C$712="AJUDANTE DE PINTURA"))} -> 2 | D20: {=SUMPRODUCT(ISNUMBER(SEARCH("741",'EFETIVO 11.05.2026'!$H$2:$H$712))*('EFETIVO 11.05.2026'!$G$2:$G$712="D")*('EFETIVO 11.05.2026'!$C$2:$C$712="AJUDANTE DE PINTURA"))} -> 4 | E20: =IFERROR(C20/$C$6,0) -> 0.010810811 | F20: {=SUMPRODUCT(ISNUMBER(SEARCH("741",'EFETIVO 11.05.2026'!$H$2:$H$712))*(('EFETIVO 11.05.2026'!$G$2:$G$712="F")+('EFETIVO 11.05.2026'!$G$2:$G$712="P")+('EFETIVO 11.05.2026'!$G$2:$G$712="T")+('EFETIVO 11.05.2026'!$G$2:$G$712="M"))*('EFETIVO 11.05.2026'!$C$2:$C$712=$B20))} -> 0
B21: AJUDANTE DE PINTURA INDUSTRIAL | C21: {=SUMPRODUCT(ISNUMBER(SEARCH("741",'EFETIVO 11.05.2026'!$H$2:$H$712))*('EFETIVO 11.05.2026'!$G$2:$G$712="A")*('EFETIVO 11.05.2026'!$C$2:$C$712="AJUDANTE DE PINTURA INDUSTRIAL"))} -> 0 | D21: {=SUMPRODUCT(ISNUMBER(SEARCH("741",'EFETIVO 11.05.2026'!$H$2:$H$712))*('EFETIVO 11.05.2026'!$G$2:$G$712="D")*('EFETIVO 11.05.2026'!$C$2:$C$712="AJUDANTE DE PINTURA INDUSTRIAL"))} -> 1 | E21: =IFERROR(C21/$C$6,0) -> 0 | F21: {=SUMPRODUCT(ISNUMBER(SEARCH("741",'EFETIVO 11.05.2026'!$H$2:$H$712))*(('EFETIVO 11.05.2026'!$G$2:$G$712="F")+('EFETIVO 11.05.2026'!$G$2:$G$712="P")+('EFETIVO 11.05.2026'!$G$2:$G$712="T")+('EFETIVO 11.05.2026'!$G$2:$G$712="M"))*('EFETIVO 11.05.2026'!$C$2:$C$712=$B21))} -> 0
B22: ALMOXARIFE | C22: {=SUMPRODUCT(ISNUMBER(SEARCH("741",'EFETIVO 11.05.2026'!$H$2:$H$712))*('EFETIVO 11.05.2026'!$G$2:$G$712="A")*('EFETIVO 11.05.2026'!$C$2:$C$712="ALMOXARIFE"))} -> 2 | D22: {=SUMPRODUCT(ISNUMBER(SEARCH("741",'EFETIVO 11.05.2026'!$H$2:$H$712))*('EFETIVO 11.05.2026'!$G$2:$G$712="D")*('EFETIVO 11.05.2026'!$C$2:$C$712="ALMOXARIFE"))} -> 0 | E22: =IFERROR(C22/$C$6,0) -> 0.010810811 | F22: {=SUMPRODUCT(ISNUMBER(SEARCH("741",'EFETIVO 11.05.2026'!$H$2:$H$712))*(('EFETIVO 11.05.2026'!$G$2:$G$712="F")+('EFETIVO 11.05.2026'!$G$2:$G$712="P")+('EFETIVO 11.05.2026'!$G$2:$G$712="T")+('EFETIVO 11.05.2026'!$G$2:$G$712="M"))*('EFETIVO 11.05.2026'!$C$2:$C$712=$B22))} -> 0
B23: ARTIFICE | C23: {=SUMPRODUCT(ISNUMBER(SEARCH("741",'EFETIVO 11.05.2026'!$H$2:$H$712))*('EFETIVO 11.05.2026'!$G$2:$G$712="A")*('EFETIVO 11.05.2026'!$C$2:$C$712="ARTIFICE"))} -> 20 | D23: {=SUMPRODUCT(ISNUMBER(SEARCH("741",'EFETIVO 11.05.2026'!$H$2:$H$712))*('EFETIVO 11.05.2026'!$G$2:$G$712="D")*('EFETIVO 11.05.2026'!$C$2:$C$712="ARTIFICE"))} -> 2 | E23: =IFERROR(C23/$C$6,0) -> 0.10810811 | F23: {=SUMPRODUCT(ISNUMBER(SEARCH("741",'EFETIVO 11.05.2026'!$H$2:$H$712))*(('EFETIVO 11.05.2026'!$G$2:$G$712="F")+('EFETIVO 11.05.2026'!$G$2:$G$712="P")+('EFETIVO 11.05.2026'!$G$2:$G$712="T")+('EFETIVO 11.05.2026'!$G$2:$G$712="M"))*('EFETIVO 11.05.2026'!$C$2:$C$712=$B23))} -> 2
B24: ASSISTENTE ADMINISTRATIVO | C24: {=SUMPRODUCT(ISNUMBER(SEARCH("741",'EFETIVO 11.05.2026'!$H$2:$H$712))*('EFETIVO 11.05.2026'!$G$2:$G$712="A")*('EFETIVO 11.05.2026'!$C$2:$C$712="ASSISTENTE ADMINISTRATIVO"))} -> 3 | D24: {=SUMPRODUCT(ISNUMBER(SEARCH("741",'EFETIVO 11.05.2026'!$H$2:$H$712))*('EFETIVO 11.05.2026'!$G$2:$G$712="D")*('EFETIVO 11.05.2026'!$C$2:$C$712="ASSISTENTE ADMINISTRATIVO"))} -> 0 | E24: =IFERROR(C24/$C$6,0) -> 0.016216216 | F24: {=SUMPRODUCT(ISNUMBER(SEARCH("741",'EFETIVO 11.05.2026'!$H$2:$H$712))*(('EFETIVO 11.05.2026'!$G$2:$G$712="F")+('EFETIVO 11.05.2026'!$G$2:$G$712="P")+('EFETIVO 11.05.2026'!$G$2:$G$712="T")+('EFETIVO 11.05.2026'!$G$2:$G$712="M"))*('EFETIVO 11.05.2026'!$C$2:$C$712=$B24))} -> 0
B25: ASSISTENTE DE LOGISTICA I | C25: {=SUMPRODUCT(ISNUMBER(SEARCH("741",'EFETIVO 11.05.2026'!$H$2:$H$712))*('EFETIVO 11.05.2026'!$G$2:$G$712="A")*('EFETIVO 11.05.2026'!$C$2:$C$712="ASSISTENTE DE LOGISTICA I"))} -> 2 | D25: {=SUMPRODUCT(ISNUMBER(SEARCH("741",'EFETIVO 11.05.2026'!$H$2:$H$712))*('EFETIVO 11.05.2026'!$G$2:$G$712="D")*('EFETIVO 11.05.2026'!$C$2:$C$712="ASSISTENTE DE LOGISTICA I"))} -> 0 | E25: =IFERROR(C25/$C$6,0) -> 0.010810811 | F25: {=SUMPRODUCT(ISNUMBER(SEARCH("741",'EFETIVO 11.05.2026'!$H$2:$H$712))*(('EFETIVO 11.05.2026'!$G$2:$G$712="F")+('EFETIVO 11.05.2026'!$G$2:$G$712="P")+('EFETIVO 11.05.2026'!$G$2:$G$712="T")+('EFETIVO 11.05.2026'!$G$2:$G$712="M"))*('EFETIVO 11.05.2026'!$C$2:$C$712=$B25))} -> 0
B26: AUXILIAR ADMINISTRATIVO | C26: {=SUMPRODUCT(ISNUMBER(SEARCH("741",'EFETIVO 11.05.2026'!$H$2:$H$712))*('EFETIVO 11.05.2026'!$G$2:$G$712="A")*('EFETIVO 11.05.2026'!$C$2:$C$712="AUXILIAR ADMINISTRATIVO"))} -> 2 | D26: {=SUMPRODUCT(ISNUMBER(SEARCH("741",'EFETIVO 11.05.2026'!$H$2:$H$712))*('EFETIVO 11.05.2026'!$G$2:$G$712="D")*('EFETIVO 11.05.2026'!$C$2:$C$712="AUXILIAR ADMINISTRATIVO"))} -> 1 | E26: =IFERROR(C26/$C$6,0) -> 0.010810811 | F26: {=SUMPRODUCT(ISNUMBER(SEARCH("741",'EFETIVO 11.05.2026'!$H$2:$H$712))*(('EFETIVO 11.05.2026'!$G$2:$G$712="F")+('EFETIVO 11.05.2026'!$G$2:$G$712="P")+('EFETIVO 11.05.2026'!$G$2:$G$712="T")+('EFETIVO 11.05.2026'!$G$2:$G$712="M"))*('EFETIVO 11.05.2026'!$C$2:$C$712=$B26))} -> 0
B27: AUXILIAR DE ALMOXARIFADO | C27: {=SUMPRODUCT(ISNUMBER(SEARCH("741",'EFETIVO 11.05.2026'!$H$2:$H$712))*('EFETIVO 11.05.2026'!$G$2:$G$712="A")*('EFETIVO 11.05.2026'!$C$2:$C$712="AUXILIAR DE ALMOXARIFADO"))} -> 2 | D27: {=SUMPRODUCT(ISNUMBER(SEARCH("741",'EFETIVO 11.05.2026'!$H$2:$H$712))*('EFETIVO 11.05.2026'!$G$2:$G$712="D")*('EFETIVO 11.05.2026'!$C$2:$C$712="AUXILIAR DE ALMOXARIFADO"))} -> 0 | E27: =IFERROR(C27/$C$6,0) -> 0.010810811 | F27: {=SUMPRODUCT(ISNUMBER(SEARCH("741",'EFETIVO 11.05.2026'!$H$2:$H$712))*(('EFETIVO 11.05.2026'!$G$2:$G$712="F")+('EFETIVO 11.05.2026'!$G$2:$G$712="P")+('EFETIVO 11.05.2026'!$G$2:$G$712="T")+('EFETIVO 11.05.2026'!$G$2:$G$712="M"))*('EFETIVO 11.05.2026'!$C$2:$C$712=$B27))} -> 0
B28: AUXILIAR DE ALMOXARIFE | C28: {=SUMPRODUCT(ISNUMBER(SEARCH("741",'EFETIVO 11.05.2026'!$H$2:$H$712))*('EFETIVO 11.05.2026'!$G$2:$G$712="A")*('EFETIVO 11.05.2026'!$C$2:$C$712="AUXILIAR DE ALMOXARIFE"))} -> 0 | D28: {=SUMPRODUCT(ISNUMBER(SEARCH("741",'EFETIVO 11.05.2026'!$H$2:$H$712))*('EFETIVO 11.05.2026'!$G$2:$G$712="D")*('EFETIVO 11.05.2026'!$C$2:$C$712="AUXILIAR DE ALMOXARIFE"))} -> 2 | E28: =IFERROR(C28/$C$6,0) -> 0 | F28: {=SUMPRODUCT(ISNUMBER(SEARCH("741",'EFETIVO 11.05.2026'!$H$2:$H$712))*(('EFETIVO 11.05.2026'!$G$2:$G$712="F")+('EFETIVO 11.05.2026'!$G$2:$G$712="P")+('EFETIVO 11.05.2026'!$G$2:$G$712="T")+('EFETIVO 11.05.2026'!$G$2:$G$712="M"))*('EFETIVO 11.05.2026'!$C$2:$C$712=$B28))} -> 0
B29: AUXILIAR DE JARDINAGEM | C29: {=SUMPRODUCT(ISNUMBER(SEARCH("741",'EFETIVO 11.05.2026'!$H$2:$H$712))*('EFETIVO 11.05.2026'!$G$2:$G$712="A")*('EFETIVO 11.05.2026'!$C$2:$C$712="AUXILIAR DE JARDINAGEM"))} -> 23 | D29: {=SUMPRODUCT(ISNUMBER(SEARCH("741",'EFETIVO 11.05.2026'!$H$2:$H$712))*('EFETIVO 11.05.2026'!$G$2:$G$712="D")*('EFETIVO 11.05.2026'!$C$2:$C$712="AUXILIAR DE JARDINAGEM"))} -> 7 | E29: =IFERROR(C29/$C$6,0) -> 0.12432432 | F29: {=SUMPRODUCT(ISNUMBER(SEARCH("741",'EFETIVO 11.05.2026'!$H$2:$H$712))*(('EFETIVO 11.05.2026'!$G$2:$G$712="F")+('EFETIVO 11.05.2026'!$G$2:$G$712="P")+('EFETIVO 11.05.2026'!$G$2:$G$712="T")+('EFETIVO 11.05.2026'!$G$2:$G$712="M"))*('EFETIVO 11.05.2026'!$C$2:$C$712=$B29))} -> 1
B30: AUXILIAR DE MANUTENCAO CIVIL | C30: {=SUMPRODUCT(ISNUMBER(SEARCH("741",'EFETIVO 11.05.2026'!$H$2:$H$712))*('EFETIVO 11.05.2026'!$G$2:$G$712="A")*('EFETIVO 11.05.2026'!$C$2:$C$712="AUXILIAR DE MANUTENCAO CIVIL"))} -> 12 | D30: {=SUMPRODUCT(ISNUMBER(SEARCH("741",'EFETIVO 11.05.2026'!$H$2:$H$712))*('EFETIVO 11.05.2026'!$G$2:$G$712="D")*('EFETIVO 11.05.2026'!$C$2:$C$712="AUXILIAR DE MANUTENCAO CIVIL"))} -> 5 | E30: =IFERROR(C30/$C$6,0) -> 0.064864865 | F30: {=SUMPRODUCT(ISNUMBER(SEARCH("741",'EFETIVO 11.05.2026'!$H$2:$H$712))*(('EFETIVO 11.05.2026'!$G$2:$G$712="F")+('EFETIVO 11.05.2026'!$G$2:$G$712="P")+('EFETIVO 11.05.2026'!$G$2:$G$712="T")+('EFETIVO 11.05.2026'!$G$2:$G$712="M"))*('EFETIVO 11.05.2026'!$C$2:$C$712=$B30))} -> 1
B31: AUXILIAR DE MANUTENCAO EM CALDEIRARIA | C31: {=SUMPRODUCT(ISNUMBER(SEARCH("741",'EFETIVO 11.05.2026'!$H$2:$H$712))*('EFETIVO 11.05.2026'!$G$2:$G$712="A")*('EFETIVO 11.05.2026'!$C$2:$C$712="AUXILIAR DE MANUTENCAO EM CALDEIRARIA"))} -> 1 | D31: {=SUMPRODUCT(ISNUMBER(SEARCH("741",'EFETIVO 11.05.2026'!$H$2:$H$712))*('EFETIVO 11.05.2026'!$G$2:$G$712="D")*('EFETIVO 11.05.2026'!$C$2:$C$712="AUXILIAR DE MANUTENCAO EM CALDEIRARIA"))} -> 0 | E31: =IFERROR(C31/$C$6,0) -> 0.0054054054 | F31: {=SUMPRODUCT(ISNUMBER(SEARCH("741",'EFETIVO 11.05.2026'!$H$2:$H$712))*(('EFETIVO 11.05.2026'!$G$2:$G$712="F")+('EFETIVO 11.05.2026'!$G$2:$G$712="P")+('EFETIVO 11.05.2026'!$G$2:$G$712="T")+('EFETIVO 11.05.2026'!$G$2:$G$712="M"))*('EFETIVO 11.05.2026'!$C$2:$C$712=$B31))} -> 0
B32: AUXILIAR DE SEGURANCA DO TRABALHO | C32: {=SUMPRODUCT(ISNUMBER(SEARCH("741",'EFETIVO 11.05.2026'!$H$2:$H$712))*('EFETIVO 11.05.2026'!$G$2:$G$712="A")*('EFETIVO 11.05.2026'!$C$2:$C$712="AUXILIAR DE SEGURANCA DO TRABALHO"))} -> 2 | D32: {=SUMPRODUCT(ISNUMBER(SEARCH("741",'EFETIVO 11.05.2026'!$H$2:$H$712))*('EFETIVO 11.05.2026'!$G$2:$G$712="D")*('EFETIVO 11.05.2026'!$C$2:$C$712="AUXILIAR DE SEGURANCA DO TRABALHO"))} -> 2 | E32: =IFERROR(C32/$C$6,0) -> 0.010810811 | F32: {=SUMPRODUCT(ISNUMBER(SEARCH("741",'EFETIVO 11.05.2026'!$H$2:$H$712))*(('EFETIVO 11.05.2026'!$G$2:$G$712="F")+('EFETIVO 11.05.2026'!$G$2:$G$712="P")+('EFETIVO 11.05.2026'!$G$2:$G$712="T")+('EFETIVO 11.05.2026'!$G$2:$G$712="M"))*('EFETIVO 11.05.2026'!$C$2:$C$712=$B32))} -> 0
B33: AUXILIAR DE SERVICOS GERAIS | C33: {=SUMPRODUCT(ISNUMBER(SEARCH("741",'EFETIVO 11.05.2026'!$H$2:$H$712))*('EFETIVO 11.05.2026'!$G$2:$G$712="A")*('EFETIVO 11.05.2026'!$C$2:$C$712="AUXILIAR DE SERVICOS GERAIS"))} -> 27 | D33: {=SUMPRODUCT(ISNUMBER(SEARCH("741",'EFETIVO 11.05.2026'!$H$2:$H$712))*('EFETIVO 11.05.2026'!$G$2:$G$712="D")*('EFETIVO 11.05.2026'!$C$2:$C$712="AUXILIAR DE SERVICOS GERAIS"))} -> 11 | E33: =IFERROR(C33/$C$6,0) -> 0.14594595 | F33: {=SUMPRODUCT(ISNUMBER(SEARCH("741",'EFETIVO 11.05.2026'!$H$2:$H$712))*(('EFETIVO 11.05.2026'!$G$2:$G$712="F")+('EFETIVO 11.05.2026'!$G$2:$G$712="P")+('EFETIVO 11.05.2026'!$G$2:$G$712="T")+('EFETIVO 11.05.2026'!$G$2:$G$712="M"))*('EFETIVO 11.05.2026'!$C$2:$C$712=$B33))} -> 1
B34: BOMBEIRO HIDRAULICO | C34: {=SUMPRODUCT(ISNUMBER(SEARCH("741",'EFETIVO 11.05.2026'!$H$2:$H$712))*('EFETIVO 11.05.2026'!$G$2:$G$712="A")*('EFETIVO 11.05.2026'!$C$2:$C$712="BOMBEIRO HIDRAULICO"))} -> 0 | D34: {=SUMPRODUCT(ISNUMBER(SEARCH("741",'EFETIVO 11.05.2026'!$H$2:$H$712))*('EFETIVO 11.05.2026'!$G$2:$G$712="D")*('EFETIVO 11.05.2026'!$C$2:$C$712="BOMBEIRO HIDRAULICO"))} -> 1 | E34: =IFERROR(C34/$C$6,0) -> 0 | F34: {=SUMPRODUCT(ISNUMBER(SEARCH("741",'EFETIVO 11.05.2026'!$H$2:$H$712))*(('EFETIVO 11.05.2026'!$G$2:$G$712="F")+('EFETIVO 11.05.2026'!$G$2:$G$712="P")+('EFETIVO 11.05.2026'!$G$2:$G$712="T")+('EFETIVO 11.05.2026'!$G$2:$G$712="M"))*('EFETIVO 11.05.2026'!$C$2:$C$712=$B34))} -> 0
B35: CADISTA I | C35: {=SUMPRODUCT(ISNUMBER(SEARCH("741",'EFETIVO 11.05.2026'!$H$2:$H$712))*('EFETIVO 11.05.2026'!$G$2:$G$712="A")*('EFETIVO 11.05.2026'!$C$2:$C$712="CADISTA I"))} -> 1 | D35: {=SUMPRODUCT(ISNUMBER(SEARCH("741",'EFETIVO 11.05.2026'!$H$2:$H$712))*('EFETIVO 11.05.2026'!$G$2:$G$712="D")*('EFETIVO 11.05.2026'!$C$2:$C$712="CADISTA I"))} -> 0 | E35: =IFERROR(C35/$C$6,0) -> 0.0054054054 | F35: {=SUMPRODUCT(ISNUMBER(SEARCH("741",'EFETIVO 11.05.2026'!$H$2:$H$712))*(('EFETIVO 11.05.2026'!$G$2:$G$712="F")+('EFETIVO 11.05.2026'!$G$2:$G$712="P")+('EFETIVO 11.05.2026'!$G$2:$G$712="T")+('EFETIVO 11.05.2026'!$G$2:$G$712="M"))*('EFETIVO 11.05.2026'!$C$2:$C$712=$B35))} -> 0
B36: CALDEIREIRO | C36: {=SUMPRODUCT(ISNUMBER(SEARCH("741",'EFETIVO 11.05.2026'!$H$2:$H$712))*('EFETIVO 11.05.2026'!$G$2:$G$712="A")*('EFETIVO 11.05.2026'!$C$2:$C$712="CALDEIREIRO"))} -> 2 | D36: {=SUMPRODUCT(ISNUMBER(SEARCH("741",'EFETIVO 11.05.2026'!$H$2:$H$712))*('EFETIVO 11.05.2026'!$G$2:$G$712="D")*('EFETIVO 11.05.2026'!$C$2:$C$712="CALDEIREIRO"))} -> 1 | E36: =IFERROR(C36/$C$6,0) -> 0.010810811 | F36: {=SUMPRODUCT(ISNUMBER(SEARCH("741",'EFETIVO 11.05.2026'!$H$2:$H$712))*(('EFETIVO 11.05.2026'!$G$2:$G$712="F")+('EFETIVO 11.05.2026'!$G$2:$G$712="P")+('EFETIVO 11.05.2026'!$G$2:$G$712="T")+('EFETIVO 11.05.2026'!$G$2:$G$712="M"))*('EFETIVO 11.05.2026'!$C$2:$C$712=$B36))} -> 0
B37: CARPINTEIRO | C37: {=SUMPRODUCT(ISNUMBER(SEARCH("741",'EFETIVO 11.05.2026'!$H$2:$H$712))*('EFETIVO 11.05.2026'!$G$2:$G$712="A")*('EFETIVO 11.05.2026'!$C$2:$C$712="CARPINTEIRO"))} -> 0 | D37: {=SUMPRODUCT(ISNUMBER(SEARCH("741",'EFETIVO 11.05.2026'!$H$2:$H$712))*('EFETIVO 11.05.2026'!$G$2:$G$712="D")*('EFETIVO 11.05.2026'!$C$2:$C$712="CARPINTEIRO"))} -> 1 | E37: =IFERROR(C37/$C$6,0) -> 0 | F37: {=SUMPRODUCT(ISNUMBER(SEARCH("741",'EFETIVO 11.05.2026'!$H$2:$H$712))*(('EFETIVO 11.05.2026'!$G$2:$G$712="F")+('EFETIVO 11.05.2026'!$G$2:$G$712="P")+('EFETIVO 11.05.2026'!$G$2:$G$712="T")+('EFETIVO 11.05.2026'!$G$2:$G$712="M"))*('EFETIVO 11.05.2026'!$C$2:$C$712=$B37))} -> 0
B38: COMPRADOR | C38: {=SUMPRODUCT(ISNUMBER(SEARCH("741",'EFETIVO 11.05.2026'!$H$2:$H$712))*('EFETIVO 11.05.2026'!$G$2:$G$712="A")*('EFETIVO 11.05.2026'!$C$2:$C$712="COMPRADOR"))} -> 2 | D38: {=SUMPRODUCT(ISNUMBER(SEARCH("741",'EFETIVO 11.05.2026'!$H$2:$H$712))*('EFETIVO 11.05.2026'!$G$2:$G$712="D")*('EFETIVO 11.05.2026'!$C$2:$C$712="COMPRADOR"))} -> 0 | E38: =IFERROR(C38/$C$6,0) -> 0.010810811 | F38: {=SUMPRODUCT(ISNUMBER(SEARCH("741",'EFETIVO 11.05.2026'!$H$2:$H$712))*(('EFETIVO 11.05.2026'!$G$2:$G$712="F")+('EFETIVO 11.05.2026'!$G$2:$G$712="P")+('EFETIVO 11.05.2026'!$G$2:$G$712="T")+('EFETIVO 11.05.2026'!$G$2:$G$712="M"))*('EFETIVO 11.05.2026'!$C$2:$C$712=$B38))} -> 0
B39: COORDENADOR DE MANUTENCAO | C39: {=SUMPRODUCT(ISNUMBER(SEARCH("741",'EFETIVO 11.05.2026'!$H$2:$H$712))*('EFETIVO 11.05.2026'!$G$2:$G$712="A")*('EFETIVO 11.05.2026'!$C$2:$C$712="COORDENADOR DE MANUTENCAO"))} -> 1 | D39: {=SUMPRODUCT(ISNUMBER(SEARCH("741",'EFETIVO 11.05.2026'!$H$2:$H$712))*('EFETIVO 11.05.2026'!$G$2:$G$712="D")*('EFETIVO 11.05.2026'!$C$2:$C$712="COORDENADOR DE MANUTENCAO"))} -> 1 | E39: =IFERROR(C39/$C$6,0) -> 0.0054054054 | F39: {=SUMPRODUCT(ISNUMBER(SEARCH("741",'EFETIVO 11.05.2026'!$H$2:$H$712))*(('EFETIVO 11.05.2026'!$G$2:$G$712="F")+('EFETIVO 11.05.2026'!$G$2:$G$712="P")+('EFETIVO 11.05.2026'!$G$2:$G$712="T")+('EFETIVO 11.05.2026'!$G$2:$G$712="M"))*('EFETIVO 11.05.2026'!$C$2:$C$712=$B39))} -> 0
B40: ELETRICISTA PREDIAL | C40: {=SUMPRODUCT(ISNUMBER(SEARCH("741",'EFETIVO 11.05.2026'!$H$2:$H$712))*('EFETIVO 11.05.2026'!$G$2:$G$712="A")*('EFETIVO 11.05.2026'!$C$2:$C$712="ELETRICISTA PREDIAL"))} -> 4 | D40: {=SUMPRODUCT(ISNUMBER(SEARCH("741",'EFETIVO 11.05.2026'!$H$2:$H$712))*('EFETIVO 11.05.2026'!$G$2:$G$712="D")*('EFETIVO 11.05.2026'!$C$2:$C$712="ELETRICISTA PREDIAL"))} -> 4 | E40: =IFERROR(C40/$C$6,0) -> 0.021621622 | F40: {=SUMPRODUCT(ISNUMBER(SEARCH("741",'EFETIVO 11.05.2026'!$H$2:$H$712))*(('EFETIVO 11.05.2026'!$G$2:$G$712="F")+('EFETIVO 11.05.2026'!$G$2:$G$712="P")+('EFETIVO 11.05.2026'!$G$2:$G$712="T")+('EFETIVO 11.05.2026'!$G$2:$G$712="M"))*('EFETIVO 11.05.2026'!$C$2:$C$712=$B40))} -> 0
B41: ENCARREGADO CIVIL | C41: {=SUMPRODUCT(ISNUMBER(SEARCH("741",'EFETIVO 11.05.2026'!$H$2:$H$712))*('EFETIVO 11.05.2026'!$G$2:$G$712="A")*('EFETIVO 11.05.2026'!$C$2:$C$712="ENCARREGADO CIVIL"))} -> 1 | D41: {=SUMPRODUCT(ISNUMBER(SEARCH("741",'EFETIVO 11.05.2026'!$H$2:$H$712))*('EFETIVO 11.05.2026'!$G$2:$G$712="D")*('EFETIVO 11.05.2026'!$C$2:$C$712="ENCARREGADO CIVIL"))} -> 4 | E41: =IFERROR(C41/$C$6,0) -> 0.0054054054 | F41: {=SUMPRODUCT(ISNUMBER(SEARCH("741",'EFETIVO 11.05.2026'!$H$2:$H$712))*(('EFETIVO 11.05.2026'!$G$2:$G$712="F")+('EFETIVO 11.05.2026'!$G$2:$G$712="P")+('EFETIVO 11.05.2026'!$G$2:$G$712="T")+('EFETIVO 11.05.2026'!$G$2:$G$712="M"))*('EFETIVO 11.05.2026'!$C$2:$C$712=$B41))} -> 0
B42: ENCARREGADO DE AREAS VERDES | C42: {=SUMPRODUCT(ISNUMBER(SEARCH("741",'EFETIVO 11.05.2026'!$H$2:$H$712))*('EFETIVO 11.05.2026'!$G$2:$G$712="A")*('EFETIVO 11.05.2026'!$C$2:$C$712="ENCARREGADO DE AREAS VERDES"))} -> 2 | D42: {=SUMPRODUCT(ISNUMBER(SEARCH("741",'EFETIVO 11.05.2026'!$H$2:$H$712))*('EFETIVO 11.05.2026'!$G$2:$G$712="D")*('EFETIVO 11.05.2026'!$C$2:$C$712="ENCARREGADO DE AREAS VERDES"))} -> 0 | E42: =IFERROR(C42/$C$6,0) -> 0.010810811 | F42: {=SUMPRODUCT(ISNUMBER(SEARCH("741",'EFETIVO 11.05.2026'!$H$2:$H$712))*(('EFETIVO 11.05.2026'!$G$2:$G$712="F")+('EFETIVO 11.05.2026'!$G$2:$G$712="P")+('EFETIVO 11.05.2026'!$G$2:$G$712="T")+('EFETIVO 11.05.2026'!$G$2:$G$712="M"))*('EFETIVO 11.05.2026'!$C$2:$C$712=$B42))} -> 0
...

Sheet EFETIVO 11.05.2026
A1: CHAPA | B1: NOME | C1: FUNÇÃO | D1: CPF | E1: ADMISSÃO | F1: DEMISSÃO | G1: SIT | H1: PROJETO | I1: BASE | J1: CARTEIRA
A2: 21283 | B2: ABIBA COSTA SALAMI MARQUES | C2: PLANEJADOR | D2: 14778656750 | E2: 45779 | F2: 45819 | G2: D | H2: PROJETO 743 - FACILITIES MULT CABIUNAS-SINTRAINDISTAL | I2: CABIUNAS
A3: 22022 | B3: ABILIO BOMFIM DA SILVA NETO | C3: PLANEJADOR | D3: 16262817778 | E3: 45826 | F3: 45964 | G3: D | H3: PROJETO 743 - FACILITIES MULT CABIUNAS-SINTRAINDISTAL | I3: CABIUNAS
A4: 22357 | B4: JULIO CESAR FERNANDES | C4: AJUDANTE DE BOMBEIRO PREDIAL | D4: 90158920759 | E4: 45840 | G4: A | H4: PROJETO 743 - FACILITIES MULT CABIUNAS-SINTRAINDISTAL | I4: BARRA DO FURADO | J4: CIVIL
A5: 20764 | B5: BRUNO SACRAMENTO SANTANA | C5: AJUDANTE DE ELETRICA PREDIAL | D5: 14215895758 | E5: 45756 | G5: A | H5: PROJETO 741 - FACILITIES MULT CABIUNAS UTE/AE-SINTRAINDISTAL | I5: AE | J5: ELETRICA
A6: 20769 | B6: ADRIANO CANDAL LEAL | C6: TECNICO DE SEGURANCA DO TRABALHO | D6: 9922726700 | E6: 45756 | F6: 45764 | G6: D | H6: PROJETO 741 - FACILITIES MULT CABIUNAS UTE/AE-SINTRAINDISTAL | I6: UTE
A7: 22919 | B7: LUIZ CESAR MADUREIRA NEVES | C7: AJUDANTE DE BOMBEIRO PREDIAL | D7: 18040867703 | E7: 45890 | G7: A | H7: PROJETO 743 - FACILITIES MULT CABIUNAS-SINTRAINDISTAL | I7: CABIUNAS | J7: CIVIL
A8: 21808 | B8: ADRIANO DA SILVA SOUSA | C8: AUXILIAR DE JARDINAGEM | D8: 16821398755 | E8: 45810 | F8: 45904 | G8: D | H8: PROJETO 743 - FACILITIES MULT CABIUNAS-SEEACEC | I8: CABIUNAS
A9: 21908 | B9: LUIZ FELIPE DA SILVA MARTINS | C9: AJUDANTE DE BOMBEIRO PREDIAL | D9: 12898637769 | E9: 45820 | G9: A | H9: PROJETO 743 - FACILITIES MULT CABIUNAS-SINTRAINDISTAL | I9: CABIUNAS | J9: CIVIL
A10: 20454 | B10: CAUA SILVA DE PAULA | C10: AJUDANTE DE ELETRICA PREDIAL | D10: 18886236751 | E10: 45729 | G10: A | H10: PROJETO 741 - FACILITIES MULT CABIUNAS UTE/AE-SINTRAINDISTAL | I10: AE | J10: ELETRICA
A11: 21753 | B11: LEONARDO STODUTO MUNIZ | C11: AJUDANTE DE ELETRICA PREDIAL | D11: 12101146746 | E11: 45810 | G11: A | H11: PROJETO 741 - FACILITIES MULT CABIUNAS UTE/AE-SINTRAINDISTAL | I11: UTE | J11: ELETRICA
A12: 21001 | B12: NATAN SAMUEL MONTEIRO FORTES | C12: AJUDANTE DE ELETRICA PREDIAL | D12: 16187094700 | E12: 45761 | G12: A | H12: PROJETO 741 - FACILITIES MULT CABIUNAS UTE/AE-SINTRAINDISTAL | I12: AE | J12: ELETRICA
A13: 21272 | B13: LUCAS OLIVEIRA DE PAULA | C13: AJUDANTE DE CALDEIRARIA PREDIAL | D13: 15467886703 | E13: 45779 | G13: A | H13: PROJETO 743 - FACILITIES MULT CABIUNAS-SINTRAINDISTAL | I13: CABIUNAS | J13: CIVIL
A14: 23249 | B14: ALDEMIR SCHWARTZ DA SILVA JUNIOR | C14: JARDINEIRO | D14: 13262226785 | E14: 45912 | F14: 46090 | G14: D | H14: PROJETO 743 - FACILITIES MULT CABIUNAS-SEEACEC | I14: CABIUNAS
A15: 20766 | B15: FILIPE LEITE DA CRUZ | C15: AJUDANTE DE ELETROMECANICA PREDIAL | D15: 19878182703 | E15: 45756 | G15: A | H15: PROJETO 741 - FACILITIES MULT CABIUNAS UTE/AE-SINTRAINDISTAL | I15: AE | J15: MECANICA
A16: 22887 | B16: LUIS GUSTAVO SILVA GEMINO | C16: AJUDANTE DE CARPINTEIRO | D16: 14081348707 | E16: 45889 | G16: A | H16: PROJETO 743 - FACILITIES MULT CABIUNAS-SINTRAINDISTAL | I16: CABIUNAS | J16: CIVIL
A17: 23762 | B17: ALESSANDRO FONTES CABRAL | C17: AUXILIAR DE SERVICOS GERAIS | D17: 16375884705 | E17: 45964 | F17: 46059 | G17: D | H17: PROJETO 741 - FACILITIES MULT CABIUNAS UTE/AE-SEEACEC
A18: 22918 | B18: THIAGO ILDEBRANDO FINAMOR | C18: AJUDANTE DE CARPINTEIRO | D18: 13096838755 | E18: 45890 | G18: A | H18: PROJETO 743 - FACILITIES MULT CABIUNAS-SINTRAINDISTAL | I18: CABIUNAS | J18: CIVIL
A19: 21777 | B19: ALEX BERNARDO RODRIGUES | C19: ESTIVAS | D19: 10112667414 | E19: 45810 | F19: 45842 | G19: D | H19: PROJETO 743 - FACILITIES MULT CABIUNAS-SINTRAINDISTAL | I19: CABIUNAS
A20: 21140 | B20: ALESSANDRO PEREIRA BORGES | C20: AJUDANTE DE ELETRICA PREDIAL | D20: 2782522574 | E20: 45772 | G20: A | H20: PROJETO 743 - FACILITIES MULT CABIUNAS-SINTRAINDISTAL | I20: CABIUNAS | J20: OPERACAO
A21: 22517 | B21: ALEX SALES DA COSTA | C21: ENCARREGADO CIVIL | D21: 12216776750 | E21: 45852 | F21: 45975 | G21: D | H21: PROJETO 741 - FACILITIES MULT CABIUNAS UTE/AE-SINTRAINDISTAL
A22: 21069 | B22: ALEX SANDRO CORREA VIANA | C22: ELETRICISTA PREDIAL | D22: 3049054700 | E22: 45763 | F22: 45847 | G22: D | H22: PROJETO 743 - FACILITIES MULT CABIUNAS-SINTRAINDISTAL | I22: CABIUNAS
A23: 23136 | B23: GABRIEL DE ALMEIDA SOUTO | C23: AJUDANTE DE ELETRICA PREDIAL | D23: 17651694708 | E23: 45903 | G23: A | H23: PROJETO 743 - FACILITIES MULT CABIUNAS-SINTRAINDISTAL | I23: CABIUNAS | J23: ELETRICA
A24: 22505 | B24: JOAO PEDRO MELLO | C24: AJUDANTE DE ELETRICA PREDIAL | D24: 15467827707 | E24: 45849 | G24: A | H24: PROJETO 743 - FACILITIES MULT CABIUNAS-SINTRAINDISTAL | I24: CABIUNAS | J24: ELETRICA
A25: 21833 | B25: JOAO VITOR CORDEIRO LUNA | C25: AJUDANTE DE ELETRICA PREDIAL | D25: 13169925784 | E25: 45810 | G25: A | H25: PROJETO 743 - FACILITIES MULT CABIUNAS-SINTRAINDISTAL | I25: CABIUNAS | J25: OPERACAO
A26: 22275 | B26: ALEXANDRE GUEDES BARBOSA | C26: AJUDANTE DE ELETRICA PREDIAL | D26: 3268742750 | E26: 45839 | F26: 46120 | G26: D | H26: PROJETO 743 - FACILITIES MULT CABIUNAS-SINTRAINDISTAL | I26: CABIUNAS
A27: 21733 | B27: ALEXANDRE SILVA SANTOS | C27: AUXILIAR DE JARDINAGEM | D27: 17214072785 | E27: 45810 | F27: 45819 | G27: D | H27: PROJETO 741 - FACILITIES MULT CABIUNAS UTE/AE-SEEACEC
A28: 21262 | B28: KENNY GABRIEL RIBEIRO TEIXEIRA | C28: AJUDANTE DE ELETROMECANICA PREDIAL | D28: 15437298781 | E28: 45779 | G28: A | H28: PROJETO 741 - FACILITIES MULT CABIUNAS UTE/AE-SINTRAINDISTAL | I28: UTE | J28: ELETRICA
A29: 21316 | B29: THIAGO CORREA SIQUEIRA | C29: AJUDANTE DE ELETROMECANICA PREDIAL | D29: 12694893724 | E29: 45779 | G29: A | H29: PROJETO 741 - FACILITIES MULT CABIUNAS UTE/AE-SINTRAINDISTAL | I29: UTE | J29: ELETRICA
A30: 21166 | B30: LUCAS NASCIMENTO FERREIRA | C30: AJUDANTE DE ELETRICA PREDIAL | D30: 19156831730 | E30: 45772 | G30: A | H30: PROJETO 743 - FACILITIES MULT CABIUNAS-SINTRAINDISTAL | I30: CABIUNAS | J30: ELETRICA
A31: 20942 | B31: JOAO FELIPE DE OLIVEIRA ALMEIDA | C31: AJUDANTE DE MANUTENCAO ELETRICA | D31: 17769571723 | E31: 45761 | G31: A | H31: PROJETO 741 - FACILITIES MULT CABIUNAS UTE/AE-SINTRAINDISTAL | I31: AE | J31: MECANICA
A32: 22892 | B32: RAFAEL ALVES DA SILVA | C32: AJUDANTE DE ELETRICA PREDIAL | D32: 6019189759 | E32: 45889 | G32: A | H32: PROJETO 743 - FACILITIES MULT CABIUNAS-SINTRAINDISTAL | I32: CABIUNAS | J32: ELETRICA
A33: 22831 | B33: ALLEFY KELVI SOUZA SANTOS | C33: ELETRICISTA PREDIAL | D33: 18498193788 | E33: 45887 | F33: 46083 | G33: D | H33: PROJETO 743 - FACILITIES MULT CABIUNAS-SINTRAINDISTAL | I33: CABIUNAS
A34: 21160 | B34: AMANDA DE CARVALHO BELO DA SILVA | C34: AUXILIAR DE SERVICOS GERAIS | D34: 16083637759 | E34: 45772 | F34: 45881 | G34: D | H34: PROJETO 743 - FACILITIES MULT CABIUNAS-SEEACEC | I34: CABIUNAS
A35: 20501 | B35: AMANDA PORTUGAL NUNES | C35: PLANEJADOR | D35: 15454281743 | E35: 45737 | F35: 45924 | G35: D | H35: PROJETO 741 - FACILITIES MULT CABIUNAS UTE/AE-SINTRAINDISTAL
A36: 21330 | B36: RHAY DINIZ BUENO MADUREIRA | C36: AJUDANTE DE ELETRICA PREDIAL | D36: 19729268703 | E36: 45779 | G36: A | H36: PROJETO 743 - FACILITIES MULT CABIUNAS-SINTRAINDISTAL | I36: CABIUNAS | J36: OPERACAO
A37: 21824 | B37: GAUDENCIO CARLOS DOS SANTOS | C37: AJUDANTE DE MECANICA PREDIAL | D37: 9304164737 | E37: 45810 | G37: A | H37: PROJETO 741 - FACILITIES MULT CABIUNAS UTE/AE-SINTRAINDISTAL | I37: UTE | J37: MECANICA
A38: 21371 | B38: MATHEUS ANDRE CARDIM | C38: AJUDANTE DE MECANICA PREDIAL | D38: 15443282735 | E38: 45782 | G38: A | H38: PROJETO 741 - FACILITIES MULT CABIUNAS UTE/AE-SINTRAINDISTAL | I38: UTE | J38: MECANICA
A39: 21780 | B39: VALMIR SILVA VIANA NETO | C39: AJUDANTE DE ELETRICA PREDIAL | D39: 19569910771 | E39: 45810 | G39: A | H39: PROJETO 743 - FACILITIES MULT CABIUNAS-SINTRAINDISTAL | I39: CABIUNAS | J39: OPERACAO
A40: 23944 | B40: JOAO PEDRO SANTOS CARDIM | C40: AJUDANTE DE MANUTENCAO ELETRICA | D40: 18389906740 | E40: 46008 | G40: A | H40: PROJETO 743 - FACILITIES MULT CABIUNAS-SINTRAINDISTAL | I40: CABIUNAS | J40: ELETRICA
...

Sheet FG-ORGANOGRAMA-743
HB21: Gerente Regional
HA22: DIEGO CASTELUBER BASSETTI
HA27: 0.2 | HB27: Gerente de Facilities | IB27: Engenheiro de Segurança | JM27: Gerente Administrativo
HA28: JOSE DANIEL SILVA SANTOS JUNIOR | IA28: RODRIGO RODRIGUES | JL28: EVANDO GERONIMO
EZ29: =SUM(EQ30+EQ32) -> 1 | GF29: =SUM(GD34,FP34,FN30) -> 9 | GT29: =SUM(GK30+GK33+GK35+GK37+GK39+GK41+GK43+GK45+GK47) -> 7.5
EQ30: 0.5 | ER30: Assistente Administrativo | FN30: 0.5 | FO30: Supervisor Administrativo | GK30: 0.5 | GL30: Supervisor de Planejamento
EQ31: GABRIEL SERAFIM DA CRUZ | FN31: MAICON MONTEIRO | GK31: CELIANE RODRIGUES DE SOUZA | IW31: =SUM(IA37+HR41+HR43+IA41+IA43+IA45+IA47+IA49+IJ41+IJ43+IJ45+IA34) -> 6 | JL31: =SUM(JC35) -> 1 | KD31: =SUM(JU35+JU37+JU39) -> 3
EQ32: 0.5 | ER32: Assistente Administrativo | IO32: Tecnico de Enfermagem | JD32: Supervisora Administrativo | JV32: Supervisor Administrativo
EQ33: RAPHAEL DURAO SENOS DE CAMPOS | GK33: 1 | GL33: Planejador | IN33: CLEITON ORILIO LIRA DA SILVA
FP34: =SUM(FG35+FG37+FG39+FG41+FG43+FG45) -> 5 | GD34: =SUM(FU35+FU37+FU39+FU41) -> 3.5 | GK34: CAMILA MAYARA VASCONCELOS XIMENES | IA34: 0.2 | IB34: Supervisora de SMS
EW35: Software | FG35: 1 | FH35: Assistente de Logistica I | FU35: 1 | FV35: Comprador - Normatel | GK35: 1 | GL35: Planejador | IA35: DANIELE LIMA PONTES | JC35: 1 | JD35: Auxiliar Administrativo | JU35: 1 | JV35: Almoxarife
FG36: POLIANE LAPA MARINS | FU36: BEATRIZ CAMPELO FERREIRA | GK36: JEMERSON DO NASCIMENTO BATISTA | JC36: TAILANE | JU36: ANA CLAUDIA DA SILVA RIBEIRO RODRIGUES
FG37: 1 | FH37: Motorista | FU37: 1 | FV37: Comprador - Petrobras | GK37: 1 | GL37: Planejador | IA37: 0.2 | IB37: Tecnico de Segurança II | JU37: 1 | JV37: Auxiliar de Almoxarife II
FG38: GEILSON CUNHA DA SILVA | FU38: DIEGO CHAGAS PIRES | GK38: LEYDIANE DA SILVA BATISTA | IA38: HERALDO JULIO GREGORIO DA SILVA | JI38: RH | JU38: KAUA DE OLIVEIRA MELEGARI DOS SANTOS
FG39: 1 | FH39: Motorista | FU39: 1 | FV39: Comprador - Petrobras | GK39: 1 | GL39: Planejador | JU39: 1 | JV39: Auxiliar de Almoxarife II
FG40: GEOVANES ADELINO DE ANDRADE FILHO | FU40: THAMYRIS BARCELOS BARRETO GONCALVES | GK40: SANDRO OLIVEIRA DA SILVA | HR40: DOCUMENTAÇÃO | IA40: ÁREA / DOCUMENTAÇÃO | IJ40: INSPEÇÃO | JU40: GLEICIANE PESSANHA BARCELOS
FG41: 1 | FH41: Motorista | FU41: 0.5 | FV41: Comprador - Petrobras | GK41: 1 | GL41: Planejador | HR41: 1 | HS41: Auxiliar de SMS | IA41: 1 | IB41: Tecnico de Segurança | IJ41: 0.2 | IK41: Tecnico de Segurança
FG42: RENAN FARIAS DE SOUZA | FU42: CRISTIANO PAIVA | GK42: ISADORA BARCELOS ALMEIDA | HR42: KEROLAYNNE NERES DE SOUZA | IA42: ANA LUIZA NASCIMENTO DA SILVA | IJ42: RAFAELA GAUDENCIO MAXIMO | KA42: Suprimentos
FG43: 0.5 | FH43: Operador de Retroesvacadeira | GK43: 1 | GL43: Assistente Administrativo | HS43: Auxiliar de SMS | IA43: 1 | IB43: Tecnico de Segurança | IJ43: 0.2 | IK43: Tecnico de Segurança
FG44: VAGA | GA44: Compras | GK44: JANKLEY CARVALHO RABELO SILVA | HR44: LUANA BATISTA LACERDA | IA44: WAGNER MACHADO MEDUREIRA | IJ44: SANDRO AUGUSTO SOUZA DO COUTO
FG45: 0.5 | FH45: Motorista Munckeiro | GK45: 1 | GL45: Auxiliar Administrativo | IA45: 1 | IB45: Tecnico de Segurança | IJ45: 0.2 | IK45: Tecnico de Segurança
FG46: UENDER DA SILVA GOMES | GK46: JULIANE GONZAGA DA SILVA | IA46: ALICIA VITORIA TENORIO DA ROCHA | IJ46: MATEUS HIPOLITO CHAGAS RIBEIRO
GL47: Auxiliar Administrativo | IA47: 1 | IB47: Tecnico de Segurança
FM48: Logística | GK48: VAGA | IA48: EM ANDAMENTO
IT50: SMS
GQ51: Planejamento
HA55: 1 | HB55: Preposto
HA56: DAIANA MARQUES
HA58: 1 | HB58: Coordenador de Manutenção
HA59: LETICIA APARECIDA CIRILO PESSANHA
HA63: CABIUNAS
EC70: =SUM(CY71,DJ75,DO81,DT85,DT87,DT89,DT91,DT93,DT95,DT97,DK85,DK87,DK89,DK91,DK93,DA85,DA87,CR85,CR87,CR89,CR91,CR93,CR95,CR97,HW162,CR99,CR101,CI85,CI87,CI89,HW160,CI91,CI93,CI111,CI95,CI97,CR80,CG75,BR80,BW85,BW87,BW89,BW91,BW95,BW97,BW99,BW101,BM85,BM87,BM89,BM91,BM95,BM97,BM99,BM101+DT75) -> 55 | HB70: =SUM(FM71,FI76,FI78,FI80,FR76,FR78,GA76,EZ76,FI84,FI86,FR84,GA84,EZ84,EH91,EH93,EH95,EH97,EQ91,EQ93,EQ95,EQ97,EQ99,EQ101,EZ91,EZ93,EZ95,EZ97,EZ99,EZ101,EZ103,EZ105,EZ107,EZ109,EZ111,EZ113,EZ115,EZ117,EZ119,EZ121,EZ123,EZ125,EZ127,EZ129,EZ131,EZ133,EZ135,EZ137,EZ139,EZ141,EZ143,FI129,FI127,FI125,FI123,FI121,FI119,FI117,FI115,FI113,FI111,FI109,FI107,FI105,FI103,FI101,FI99,FI97,FI95,FI93,FI91,FR91,FR93,FR95,FR97,FR99,FR101,GA99,GA97,GA95,GA93,GA91,GJ91,GJ93,GJ95,GJ97,GJ99,GJ101,GS99,GS97,GS95,GS93,GS91) -> 89.4 | JF70: =SUM(IC71,IC75,IM78,IC82,HN82,IR82,HI85,HS85,IC85,IM85,IW85,IW87,IM87,IC87,HS87,HI87,HI89,HS91,IC89,FR162,FR166,IW91,FR160,IC91,HS93,HI91,HI93,HS95,IC93,IM89,IW93,IW95,IM91,IC95,HS97,HI95,HI97,HS99,IC97,IM93,IW97,IW99,IM95,IC99,HS101,HI99,HI101,HS103,IC101,IM97,IW101,IW103,IW105,IW107,IW109,IW111,IW113,IM107,IM109,IM105,IM103,IM101,FR164,IM99,IC103,IC105,FR168,IC107,IC109,IC111,IC113,IW89,HS115,HR111,HS113,HS111,HS109,HS107,HS105,HI103,HI105,HI107,HI109,HI111,HI113,HI115,HS89) -> 85.2 | KW70: =SUM(JZ71+KJ75+JP75+JK78+JU78+KE78+KO80+KE80,JU80,JK80,JK82,JU82,KE82,KO82,KO84,KO86,KO88,KO90,KO92,KO94,KO96,KO98,KO100,KO102,KO104,KE84,KE86,KE88,KE90,KE92,KE94,KE96,KE98,KE100,KE102,JU84,JU86,JU88,JU90,JU92,JU94,JU96,JU98,JU100,JU102,JK84,JK86,JK88,JK90,JK92,JK94,JK96,JK98,JK100) -> 54
CY71: 1 | CZ71: Engenheiro de Eletrica | FM71: 0.5 | FN71: Engenheira Civil | IC71: 0.2 | ID71: Engenheiro Agronomo | JZ71: 1 | KA71: Supervisor de Limpeza
CY72: DANIEL DOS SANTOS NASCIMENTO | FM72: GABRIELLA RODRIGUES PINTO | IC72: GUSTAVO FABRI BASTOS | JZ72: ELAINE EUGENIO DA SILVA
CG75: 1 | CH75: Supervisor de Eletrica | DJ75: 1 | DK75: Supervisor de Refrigeração | DT75: 1 | DU75: Cadista | EZ75: DRONE | FI75: SUPERVISÃO OPERACIONAL | FR75: SUPERVISÃO ADMINISTRATIVA | GA75: GESTÃO DE OCUPACAO | IC75: 1 | ID75: Supervisor de Áreas Verdes | JP75: 1 | JQ75: Encarregado de Limpeza | KJ75: 1 | KK75: Encarregado de Limpeza
CG76: THIAGO DA SILVA | DJ76: WENDERSON DE SOUZA FURTADO | DT76: KAIO KNUPP | EZ76: 0.2 | FA76: Operador de RPAS | FI76: 1 | FJ76: Supervisor de Manutencao Civil | FR76: 1 | FS76: Supervisor de Manutencao Civil | GA76: 0.2 | GB76: Auxiliar Administrativo | IC76: MAGNO CANDEIAS PEREIRA | JP76: VALDENICE DOS SANTOS LEMOS | KJ76: ELAINE LOPES FREITAS GONZAGA
EZ77: DIEGO WAGNER MARTINS DA SILVA | FI77: LEONARDO NUNES FIRMINO | FR77: ANTONIO CESAR BATISTA DE ALMEIDA | GA77: DANIEL MAIA DA SILVA | IM77: APOIO TECNICO
FI78: 1 | FJ78: Inspetor Predial | FR78: 1 | FS78: Cadista | IM78: 1 | IN78: Tecnico Agronomo | JK78: 1 | JL78: Auxiliar de Serviços Gerais | JU78: 1 | JV78: Auxiliar de Serviços Gerais | KE78: 1 | KF78: Auxiliar de Serviços Gerais | KO78: 1 | KP78: Auxiliar de Serviços Gerais
FI79: WILLIAM COSME MANHAES DILAIS | FR79: ARGOS MATHEUS SOUZA LOPES | IM79: ALEX PIMENTA BENTO | JK79: ADELSON LEITE DA SILVA | JU79: AFRICA DE AZEVEDO NEVES CARINO | KE79: ALEX SANDRO PIZIO DA SILVA | KO79: ANA CELIA DE OLIVEIRA SANTOS
BR80: 1 | BS80: Operador | CR80: 1 | CS80: Encarregado de Elétrica | FI80: 1 | FJ80: Auxiliar de Manutencao Civil | JK80: 1 | JL80: Auxiliar de Serviços Gerais | JU80: 1 | JV80: Auxiliar de Serviços Gerais | KE80: 1 | KF80: Auxiliar de Serviços Gerais | KO80: 1 | KP80: Auxiliar de Serviços Gerais
...

Sheet ORG-RESUMIDO-743
X3: Gerente Regional
W4: DIEGO CASTELUBER BASSETTI
W7: 0.5 | X7: Gerente de Facilites | AX7: Gerente de SMS | BK7: Gerente ADM
W8: JOSE DANIEL SILVA SANTOS JUNIOR | AW8: RODRIGO CESAR RODRIGUES | BJ8: EVANDO GERONIMO
P10: EQUIPE ESTRATÉGICA
P11: GERÊNCIA DE INTEGRAÇÃO | AX11: QUALIDADE, SAÚDE SEGURANÇA E MEIO AMBIENTE | BB11: EQUIPE DE SAUDE | BK11: RH | BO11: ALMOXARIFADO
M15: 0.5 | N15: Assistente Administrativo | W15: ='FG-ORGANOGRAMA-741'!BG13 -> 0.5 | X15: Supervisor Administrativo | AG15: ='FG-ORGANOGRAMA-741'!CD13 -> 1 | AH15: Supervisora de Planejamento
M16: GABRIEL SERAFIM DA CRUZ | W16: MAICON MONTEIRO | AG16: CELIANE RODRIGUES DE SOUZA
P18: SOFTWARE | X18: LOGÍSTICA | AA18: COMPRAS | AJ18: PLANEJAMENTO
AX21: ='FG-ORGANOGRAMA-743'!IW31 -> 6 | BB21: 0 | BK21: ='FG-ORGANOGRAMA-743'!JL31 -> 1 | BO21: ='FG-ORGANOGRAMA-743'!KD31 -> 3
P28: ='FG-ORGANOGRAMA-743'!EZ29 -> 1 | X28: ='FG-ORGANOGRAMA-743'!FP34 -> 5 | AA28: ='FG-ORGANOGRAMA-743'!GD34 -> 3.5 | AJ28: ='FG-ORGANOGRAMA-743'!GT29 -> 7.5
AO33: 1 | AP33: Preposto
AO34: DAIANA MARQUES
AO36: 1 | AP36: Coordenador de Manutenção
AO37: LETICIA APARECIDA CIRILO PESSANHA
T40: Cabiunas | AQ40: Fazenda Severina | BN40: Barra do Furado
H44: 0.5 | I44: Engenheiro Eletricista | R44: 0.5 | S44: Engenheiro Civil | AB44: 0.5 | AC44: Engenheiro Agronomo | BB44: 0.5 | BC44: Engenheiro Eletricista | BL44: 0.5 | BM44: Engenheiro Civil | BV44: 0.5 | BW44: Engenheiro Agronomo
H45: DANIEL DOS SANTOS NASCIMENTO | R45: GABRIELLA RODRIGUES PINTO | AB45: GUSTAVO FABRI BASTOS | BB45: DANIEL DOS SANTOS NASCIMENTO | BL45: GABRIELLA RODRIGUES PINTO | BV45: GUSTAVO FABRI BASTOS
K47: MANUTENÇÃO | U47: CIVIL | AD47: ÁREAS VERDES | AG47: CONS. LIMPEZA | AR47: CONS. LIMPEZA | BE47: MANUTENÇÃO | BO47: CIVIL | BX47: ÁREAS VERDES | CA47: CONS. LIMPEZA
K57: ='FG-ORGANOGRAMA-743'!EC70 -> 55 | U57: ='FG-ORGANOGRAMA-743'!HB70 -> 89.4 | AD57: ='FG-ORGANOGRAMA-743'!JF70 -> 85.2 | AG57: ='FG-ORGANOGRAMA-743'!KW70 -> 54 | AR57: ='FG-ORGANOGRAMA-743'!HJ181 -> 1 | BE57: ='FG-ORGANOGRAMA-743'!IF158 -> 2 | BO57: ='FG-ORGANOGRAMA-743'!HS158 -> 6 | BX57: ='FG-ORGANOGRAMA-743'!GA158 -> 5 | CA57: ='FG-ORGANOGRAMA-743'!GN158 -> 5
AM64: TOTAL | AQ64: =SUM(W3+W7+M15+W15+AG15+P28+X28+AA28+AJ28+AW7+AX21+BB21+BJ7+BK21+BO21+AO33+AO36+H44+R44+AB44+K57+U57+AD57+AG57+AO44+BB44+BE57+BL44+BO57+BV44+BX57+AR57) -> 332.1

Sheet Análises 743 1
A1: NORMATEL • Análises Projeto 743
A2: Cálculos dinâmicos sobre EFETIVO 11.05.2026 - Situações (SIT): A=Ativo, D=Desligado, F=Férias, P=INSS, T=Acidente de Trabalho, M=Serviço Militar
B4: 1. Indicadores do Projeto 743
B5: Total de registros vinculados ao 743 (todas situações) | C5: {=SUMPRODUCT(ISNUMBER(SEARCH("743",'EFETIVO 11.05.2026'!$H$2:$H$712))*(('EFETIVO 11.05.2026'!$G$2:$G$712="A")+('EFETIVO 11.05.2026'!$G$2:$G$712="D")+('EFETIVO 11.05.2026'!$G$2:$G$712="F")+('EFETIVO 11.05.2026'!$G$2:$G$712="P")+('EFETIVO 11.05.2026'!$G$2:$G$712="T")+('EFETIVO 11.05.2026'!$G$2:$G$712="M")))} -> 433
B6: Ativos no 743 | C6: {=SUMPRODUCT(ISNUMBER(SEARCH("743",'EFETIVO 11.05.2026'!$H$2:$H$712))*('EFETIVO 11.05.2026'!$G$2:$G$712="A"))} -> 319
B7: Desligados no 743 | C7: {=SUMPRODUCT(ISNUMBER(SEARCH("743",'EFETIVO 11.05.2026'!$H$2:$H$712))*('EFETIVO 11.05.2026'!$G$2:$G$712="D"))} -> 101
B8: % de turnover (desligados / total) | C8: =IFERROR(C7/C5,0) -> 0.23325635
B9: Afastados no 743 (F+P+T+M) | C9: {=SUMPRODUCT(ISNUMBER(SEARCH("743",'EFETIVO 11.05.2026'!$H$2:$H$712))*(('EFETIVO 11.05.2026'!$G$2:$G$712="F")+('EFETIVO 11.05.2026'!$G$2:$G$712="P")+('EFETIVO 11.05.2026'!$G$2:$G$712="T")+('EFETIVO 11.05.2026'!$G$2:$G$712="M")))} -> 13
B10: Funções distintas (somente ativos) | C10: {=SUMPRODUCT(--(C15:C89>0))} -> 66
B12: 2. Headcount por Função (Ativos / Desligados / Afastados)
B14: Função | C14: Ativos | D14: Desligados | E14: % do total ativos | F14: Afastados
B15: AJUDANTE DE BOMBEIRO PREDIAL | C15: {=SUMPRODUCT(ISNUMBER(SEARCH("743",'EFETIVO 11.05.2026'!$H$2:$H$712))*('EFETIVO 11.05.2026'!$G$2:$G$712="A")*('EFETIVO 11.05.2026'!$C$2:$C$712=B15))} -> 3 | D15: {=SUMPRODUCT(ISNUMBER(SEARCH("743",'EFETIVO 11.05.2026'!$H$2:$H$712))*('EFETIVO 11.05.2026'!$G$2:$G$712="D")*('EFETIVO 11.05.2026'!$C$2:$C$712=B15))} -> 1 | E15: =IFERROR(C15/$C$6,0) -> 0.0094043887 | F15: {=SUMPRODUCT(ISNUMBER(SEARCH("743",'EFETIVO 11.05.2026'!$H$2:$H$712))*(('EFETIVO 11.05.2026'!$G$2:$G$712="F")+('EFETIVO 11.05.2026'!$G$2:$G$712="P")+('EFETIVO 11.05.2026'!$G$2:$G$712="T")+('EFETIVO 11.05.2026'!$G$2:$G$712="M"))*('EFETIVO 11.05.2026'!$C$2:$C$712=$B15))} -> 0
B16: AJUDANTE DE CALDEIRARIA PREDIAL | C16: {=SUMPRODUCT(ISNUMBER(SEARCH("743",'EFETIVO 11.05.2026'!$H$2:$H$712))*('EFETIVO 11.05.2026'!$G$2:$G$712="A")*('EFETIVO 11.05.2026'!$C$2:$C$712=B16))} -> 1 | D16: {=SUMPRODUCT(ISNUMBER(SEARCH("743",'EFETIVO 11.05.2026'!$H$2:$H$712))*('EFETIVO 11.05.2026'!$G$2:$G$712="D")*('EFETIVO 11.05.2026'!$C$2:$C$712=B16))} -> 3 | E16: =IFERROR(C16/$C$6,0) -> 0.0031347962 | F16: {=SUMPRODUCT(ISNUMBER(SEARCH("743",'EFETIVO 11.05.2026'!$H$2:$H$712))*(('EFETIVO 11.05.2026'!$G$2:$G$712="F")+('EFETIVO 11.05.2026'!$G$2:$G$712="P")+('EFETIVO 11.05.2026'!$G$2:$G$712="T")+('EFETIVO 11.05.2026'!$G$2:$G$712="M"))*('EFETIVO 11.05.2026'!$C$2:$C$712=$B16))} -> 0
B17: AJUDANTE DE CARPINTEIRO | C17: {=SUMPRODUCT(ISNUMBER(SEARCH("743",'EFETIVO 11.05.2026'!$H$2:$H$712))*('EFETIVO 11.05.2026'!$G$2:$G$712="A")*('EFETIVO 11.05.2026'!$C$2:$C$712=B17))} -> 2 | D17: {=SUMPRODUCT(ISNUMBER(SEARCH("743",'EFETIVO 11.05.2026'!$H$2:$H$712))*('EFETIVO 11.05.2026'!$G$2:$G$712="D")*('EFETIVO 11.05.2026'!$C$2:$C$712=B17))} -> 1 | E17: =IFERROR(C17/$C$6,0) -> 0.0062695925 | F17: {=SUMPRODUCT(ISNUMBER(SEARCH("743",'EFETIVO 11.05.2026'!$H$2:$H$712))*(('EFETIVO 11.05.2026'!$G$2:$G$712="F")+('EFETIVO 11.05.2026'!$G$2:$G$712="P")+('EFETIVO 11.05.2026'!$G$2:$G$712="T")+('EFETIVO 11.05.2026'!$G$2:$G$712="M"))*('EFETIVO 11.05.2026'!$C$2:$C$712=$B17))} -> 0
B18: AJUDANTE DE ELETRICA PREDIAL | C18: {=SUMPRODUCT(ISNUMBER(SEARCH("743",'EFETIVO 11.05.2026'!$H$2:$H$712))*('EFETIVO 11.05.2026'!$G$2:$G$712="A")*('EFETIVO 11.05.2026'!$C$2:$C$712=B18))} -> 8 | D18: {=SUMPRODUCT(ISNUMBER(SEARCH("743",'EFETIVO 11.05.2026'!$H$2:$H$712))*('EFETIVO 11.05.2026'!$G$2:$G$712="D")*('EFETIVO 11.05.2026'!$C$2:$C$712=B18))} -> 3 | E18: =IFERROR(C18/$C$6,0) -> 0.02507837 | F18: {=SUMPRODUCT(ISNUMBER(SEARCH("743",'EFETIVO 11.05.2026'!$H$2:$H$712))*(('EFETIVO 11.05.2026'!$G$2:$G$712="F")+('EFETIVO 11.05.2026'!$G$2:$G$712="P")+('EFETIVO 11.05.2026'!$G$2:$G$712="T")+('EFETIVO 11.05.2026'!$G$2:$G$712="M"))*('EFETIVO 11.05.2026'!$C$2:$C$712=$B18))} -> 0
B19: AJUDANTE DE ELETROMECANICA PREDIAL | C19: {=SUMPRODUCT(ISNUMBER(SEARCH("743",'EFETIVO 11.05.2026'!$H$2:$H$712))*('EFETIVO 11.05.2026'!$G$2:$G$712="A")*('EFETIVO 11.05.2026'!$C$2:$C$712=B19))} -> 0 | D19: {=SUMPRODUCT(ISNUMBER(SEARCH("743",'EFETIVO 11.05.2026'!$H$2:$H$712))*('EFETIVO 11.05.2026'!$G$2:$G$712="D")*('EFETIVO 11.05.2026'!$C$2:$C$712=B19))} -> 1 | E19: =IFERROR(C19/$C$6,0) -> 0 | F19: {=SUMPRODUCT(ISNUMBER(SEARCH("743",'EFETIVO 11.05.2026'!$H$2:$H$712))*(('EFETIVO 11.05.2026'!$G$2:$G$712="F")+('EFETIVO 11.05.2026'!$G$2:$G$712="P")+('EFETIVO 11.05.2026'!$G$2:$G$712="T")+('EFETIVO 11.05.2026'!$G$2:$G$712="M"))*('EFETIVO 11.05.2026'!$C$2:$C$712=$B19))} -> 0
B20: AJUDANTE DE MANUTENCAO ELETRICA | C20: {=SUMPRODUCT(ISNUMBER(SEARCH("743",'EFETIVO 11.05.2026'!$H$2:$H$712))*('EFETIVO 11.05.2026'!$G$2:$G$712="A")*('EFETIVO 11.05.2026'!$C$2:$C$712=B20))} -> 4 | D20: {=SUMPRODUCT(ISNUMBER(SEARCH("743",'EFETIVO 11.05.2026'!$H$2:$H$712))*('EFETIVO 11.05.2026'!$G$2:$G$712="D")*('EFETIVO 11.05.2026'!$C$2:$C$712=B20))} -> 0 | E20: =IFERROR(C20/$C$6,0) -> 0.012539185 | F20: {=SUMPRODUCT(ISNUMBER(SEARCH("743",'EFETIVO 11.05.2026'!$H$2:$H$712))*(('EFETIVO 11.05.2026'!$G$2:$G$712="F")+('EFETIVO 11.05.2026'!$G$2:$G$712="P")+('EFETIVO 11.05.2026'!$G$2:$G$712="T")+('EFETIVO 11.05.2026'!$G$2:$G$712="M"))*('EFETIVO 11.05.2026'!$C$2:$C$712=$B20))} -> 0
B21: AJUDANTE DE MARCENEIRO | C21: {=SUMPRODUCT(ISNUMBER(SEARCH("743",'EFETIVO 11.05.2026'!$H$2:$H$712))*('EFETIVO 11.05.2026'!$G$2:$G$712="A")*('EFETIVO 11.05.2026'!$C$2:$C$712=B21))} -> 2 | D21: {=SUMPRODUCT(ISNUMBER(SEARCH("743",'EFETIVO 11.05.2026'!$H$2:$H$712))*('EFETIVO 11.05.2026'!$G$2:$G$712="D")*('EFETIVO 11.05.2026'!$C$2:$C$712=B21))} -> 0 | E21: =IFERROR(C21/$C$6,0) -> 0.0062695925 | F21: {=SUMPRODUCT(ISNUMBER(SEARCH("743",'EFETIVO 11.05.2026'!$H$2:$H$712))*(('EFETIVO 11.05.2026'!$G$2:$G$712="F")+('EFETIVO 11.05.2026'!$G$2:$G$712="P")+('EFETIVO 11.05.2026'!$G$2:$G$712="T")+('EFETIVO 11.05.2026'!$G$2:$G$712="M"))*('EFETIVO 11.05.2026'!$C$2:$C$712=$B21))} -> 0
B22: AJUDANTE DE MECANICA PREDIAL | C22: {=SUMPRODUCT(ISNUMBER(SEARCH("743",'EFETIVO 11.05.2026'!$H$2:$H$712))*('EFETIVO 11.05.2026'!$G$2:$G$712="A")*('EFETIVO 11.05.2026'!$C$2:$C$712=B22))} -> 3 | D22: {=SUMPRODUCT(ISNUMBER(SEARCH("743",'EFETIVO 11.05.2026'!$H$2:$H$712))*('EFETIVO 11.05.2026'!$G$2:$G$712="D")*('EFETIVO 11.05.2026'!$C$2:$C$712=B22))} -> 1 | E22: =IFERROR(C22/$C$6,0) -> 0.0094043887 | F22: {=SUMPRODUCT(ISNUMBER(SEARCH("743",'EFETIVO 11.05.2026'!$H$2:$H$712))*(('EFETIVO 11.05.2026'!$G$2:$G$712="F")+('EFETIVO 11.05.2026'!$G$2:$G$712="P")+('EFETIVO 11.05.2026'!$G$2:$G$712="T")+('EFETIVO 11.05.2026'!$G$2:$G$712="M"))*('EFETIVO 11.05.2026'!$C$2:$C$712=$B22))} -> 0
B23: AJUDANTE DE PEDREIRO | C23: {=SUMPRODUCT(ISNUMBER(SEARCH("743",'EFETIVO 11.05.2026'!$H$2:$H$712))*('EFETIVO 11.05.2026'!$G$2:$G$712="A")*('EFETIVO 11.05.2026'!$C$2:$C$712=B23))} -> 8 | D23: {=SUMPRODUCT(ISNUMBER(SEARCH("743",'EFETIVO 11.05.2026'!$H$2:$H$712))*('EFETIVO 11.05.2026'!$G$2:$G$712="D")*('EFETIVO 11.05.2026'!$C$2:$C$712=B23))} -> 2 | E23: =IFERROR(C23/$C$6,0) -> 0.02507837 | F23: {=SUMPRODUCT(ISNUMBER(SEARCH("743",'EFETIVO 11.05.2026'!$H$2:$H$712))*(('EFETIVO 11.05.2026'!$G$2:$G$712="F")+('EFETIVO 11.05.2026'!$G$2:$G$712="P")+('EFETIVO 11.05.2026'!$G$2:$G$712="T")+('EFETIVO 11.05.2026'!$G$2:$G$712="M"))*('EFETIVO 11.05.2026'!$C$2:$C$712=$B23))} -> 2
